Workbook

Sheet Simulador
A1: SIMULADOR CUT OFF | E1: ANTES | L1: DEPOIS | S1: DELTA | Z1: Efetivadas = jun/26, jul/26
E2: # Efeti | F2: Txa Apr | G2: %FPD $ | H2: %O30M2 $ | I2: %O30M3 $ | J2: %O60M6 $ | L2: # Efeti | M2: Txa Apr | N2: %FPD $ | O2: %O30M2 $ | P2: %O30M3 $ | Q2: %O60M6 $ | S2: Δ Efeti | T2: Δ $ Vl. Primeira Fatura | U2: Δ $ Saldo Mob 2 | V2: Δ $ Saldo Mob 3 | W2: Δ $ Saldo Mob 6 | Z2: FPD = mar/26, abr/26, mai/26
D3: GERAL | E3: =BS_CONSOLIDADO!D4 -> 7559 | F3: =BS_CONSOLIDADO!Q4 -> 0.17993221 | G3: =BS_CONSOLIDADO!M4 -> 0.10580333 | H3: =BS_CONSOLIDADO!N4 -> 0.086896166 | I3: =BS_CONSOLIDADO!O4 -> 0.13901439 | J3: =BS_CONSOLIDADO!P4 -> 0.20534061 | L3: =E3-(-S3) -> 7559 | M3: =IF(COUNTBLANK(L6)=1,F3,(BS_CONSOLIDADO!C4-BS_SIMULADOR!T5)/(BS_CONSOLIDADO!B4-BS_SIMULADOR!S5)) -> 0.17993221 | N3: =IF(COUNTBLANK($L6)=1,G3,(BS_CONSOLIDADO!E4-BS_SIMULADOR!V5)/(BS_CONSOLIDADO!F4-BS_SIMULADOR!W5)) -> 0.10580333 | O3: =IF(COUNTBLANK($L6)=1,H3,(BS_CONSOLIDADO!G4-BS_SIMULADOR!X5)/(BS_CONSOLIDADO!H4-BS_SIMULADOR!Y5)) -> 0.086896166 | P3: =IF(COUNTBLANK($L6)=1,I3,(BS_CONSOLIDADO!I4-BS_SIMULADOR!Z5)/(BS_CONSOLIDADO!J4-BS_SIMULADOR!AA5)) -> 0.13901439 | Q3: =IF(COUNTBLANK(L6)=1,J3,(BS_CONSOLIDADO!K4-BS_SIMULADOR!AB5)/(BS_CONSOLIDADO!L4-BS_SIMULADOR!AC5)) -> 0.20534061 | S3: =SUM(S6:S400) -> 0 | T3: =SUM(T6:T400) -> 0 | U3: =SUM(U6:U400) -> 0 | V3: =SUM(V6:V400) -> 0 | W3: =SUM(W6:W400) -> 0 | Z3: Over30M2 = mar/26, abr/26, mai/26
B4: =COUNTA(B6:B400) -> 1 | Z4: Over30M3 = fev/26, mar/26, abr/26
A5: {=_xlfn.UNIQUE(_xlfn._xlws.FILTER(bs_propostas!A:A, bs_propostas!A:A <> ""))} -> Parceiro | B5: Cut Off | D5: Parceiros Selecionados | E5: # Efeti | F5: Txa Apr | G5: %FPD $ | H5: %O30M2 $ | I5: %O30M3 $ | J5: %O60M6 $ | L5: # Efeti | M5: Txa Apr | N5: %FPD $ | O5: %O30M2 $ | P5: %O30M3 $ | Q5: %O60M6 $ | S5: Δ Efeti | T5: Δ $ Vl. Primeira Fatura | U5: Δ $ Saldo Mob 2 | V5: Δ $ Saldo Mob 3 | W5: Δ $ Saldo Mob 6 | Z5: Over60M6 = nov/25, dez/25, jan/26
A6: Parceiro 1 | D6: {=_xlfn.UNIQUE(_xlfn._xlws.FILTER(A6:A400, B6:B400 <> "", ""))} -> Parceiro 17 | E6: =IF(COUNTBLANK(D6)=1,"",_xlfn.XLOOKUP(D6,BS_CONSOLIDADO!A:A,BS_CONSOLIDADO!D:D,"")) -> 943 | F6: =IF(COUNTBLANK(D6)=1,"",_xlfn.XLOOKUP(D6,BS_CONSOLIDADO!A:A,BS_CONSOLIDADO!Q:Q,"")) -> 0.2099882 | G6: =IF(COUNTBLANK($D6)=1,"",_xlfn.XLOOKUP($D6,BS_CONSOLIDADO!$A:$A,BS_CONSOLIDADO!M:M,"")) -> 0.1082029 | H6: =IF(COUNTBLANK($D6)=1,"",_xlfn.XLOOKUP($D6,BS_CONSOLIDADO!$A:$A,BS_CONSOLIDADO!N:N,"")) -> 0.092431944 | I6: =IF(COUNTBLANK(D6)=1,"",_xlfn.XLOOKUP(D6,BS_CONSOLIDADO!A:A,BS_CONSOLIDADO!O:O,"")) -> 0.16626681 | J6: =IF(COUNTBLANK(D6)=1,"",_xlfn.XLOOKUP(D6,BS_CONSOLIDADO!A:A,BS_CONSOLIDADO!P:P,"")) -> 0.23754568 | L6: =IF(COUNTBLANK(D6)=1,"",_xlfn.XLOOKUP(D6,BS_SIMULADOR!A:A,BS_SIMULADOR!D:D,"")) -> 943 | M6: =IF(COUNTBLANK(D6)=1,"",_xlfn.XLOOKUP(D6,BS_SIMULADOR!A:A,BS_SIMULADOR!Q:Q,"")) -> 0.2099882 | N6: =IF(COUNTBLANK($D6)=1,"",_xlfn.XLOOKUP($D6,BS_SIMULADOR!$A:$A,BS_SIMULADOR!M:M,"")) -> 0.1082029 | O6: =IF(COUNTBLANK($D6)=1,"",_xlfn.XLOOKUP($D6,BS_SIMULADOR!$A:$A,BS_SIMULADOR!N:N,"")) -> 0.092431944 | P6: =IF(COUNTBLANK($D6)=1,"",_xlfn.XLOOKUP($D6,BS_SIMULADOR!$A:$A,BS_SIMULADOR!O:O,"")) -> 0.16626681 | Q6: =IF(COUNTBLANK($D6)=1,"",_xlfn.XLOOKUP($D6,BS_SIMULADOR!$A:$A,BS_SIMULADOR!P:P,"")) -> 0.23754568 | S6: =IFERROR(IF(COUNTBLANK(D6)=1,"",E6-L6)*(-1),"") -> 0 | T6: =IFERROR(IF(COUNTBLANK($D6)=1,"",(_xlfn.XLOOKUP($D6,BS_CONSOLIDADO!$A:$A,BS_CONSOLIDADO!F:F,""))-(_xlfn.XLOOKUP($D6,BS_SIMULADOR!$A:$A,BS_SIMULADOR!F:F,"")))*(-1),"") -> 0 | U6: =IFERROR(IF(COUNTBLANK($D6)=1,"",(_xlfn.XLOOKUP($D6,BS_CONSOLIDADO!$A:$A,BS_CONSOLIDADO!H:H,""))-(_xlfn.XLOOKUP($D6,BS_SIMULADOR!$A:$A,BS_SIMULADOR!H:H,"")))*(-1),"") -> 0 | V6: =IFERROR(IF(COUNTBLANK($D6)=1,"",(_xlfn.XLOOKUP($D6,BS_CONSOLIDADO!$A:$A,BS_CONSOLIDADO!J:J,""))-(_xlfn.XLOOKUP($D6,BS_SIMULADOR!$A:$A,BS_SIMULADOR!J:J,"")))*(-1),"") -> 0 | W6: =IFERROR(IF(COUNTBLANK($D6)=1,"",(_xlfn.XLOOKUP($D6,BS_CONSOLIDADO!$A:$A,BS_CONSOLIDADO!L:L,""))-(_xlfn.XLOOKUP($D6,BS_SIMULADOR!$A:$A,BS_SIMULADOR!L:L,"")))*(-1),"") -> 0
A7: Parceiro 2 | E7: =IF(COUNTBLANK(D7)=1,"",_xlfn.XLOOKUP(D7,BS_CONSOLIDADO!A:A,BS_CONSOLIDADO!D:D,"")) | F7: =IF(COUNTBLANK(D7)=1,"",_xlfn.XLOOKUP(D7,BS_CONSOLIDADO!A:A,BS_CONSOLIDADO!Q:Q,"")) | G7: =IF(COUNTBLANK($D7)=1,"",_xlfn.XLOOKUP($D7,BS_CONSOLIDADO!$A:$A,BS_CONSOLIDADO!M:M,"")) | H7: =IF(COUNTBLANK(D7)=1,"",_xlfn.XLOOKUP(D7,BS_CONSOLIDADO!A:A,BS_CONSOLIDADO!N:N,"")) | I7: =IF(COUNTBLANK(D7)=1,"",_xlfn.XLOOKUP(D7,BS_CONSOLIDADO!A:A,BS_CONSOLIDADO!O:O,"")) | J7: =IF(COUNTBLANK(D7)=1,"",_xlfn.XLOOKUP(D7,BS_CONSOLIDADO!A:A,BS_CONSOLIDADO!P:P,"")) | L7: =IF(COUNTBLANK(D7)=1,"",_xlfn.XLOOKUP(D7,BS_SIMULADOR!A:A,BS_SIMULADOR!D:D,"")) | M7: =IF(COUNTBLANK(D7)=1,"",_xlfn.XLOOKUP(D7,BS_SIMULADOR!A:A,BS_SIMULADOR!Q:Q,"")) | N7: =IF(COUNTBLANK($D7)=1,"",_xlfn.XLOOKUP($D7,BS_SIMULADOR!$A:$A,BS_SIMULADOR!M:M,"")) | O7: =IF(COUNTBLANK(D7)=1,"",_xlfn.XLOOKUP(D7,BS_SIMULADOR!A:A,BS_SIMULADOR!N:N,"")) | P7: =IF(COUNTBLANK(D7)=1,"",_xlfn.XLOOKUP(D7,BS_SIMULADOR!A:A,BS_SIMULADOR!O:O,"")) | Q7: =IF(COUNTBLANK($D7)=1,"",_xlfn.XLOOKUP($D7,BS_SIMULADOR!$A:$A,BS_SIMULADOR!P:P,"")) | S7: =IFERROR(IF(COUNTBLANK(D7)=1,"",E7-L7)*(-1),"") | T7: =IFERROR(IF(COUNTBLANK($D7)=1,"",(_xlfn.XLOOKUP($D7,BS_CONSOLIDADO!$A:$A,BS_CONSOLIDADO!F:F,""))-(_xlfn.XLOOKUP($D7,BS_SIMULADOR!$A:$A,BS_SIMULADOR!F:F,"")))*(-1),"") | U7: =IFERROR(IF(COUNTBLANK(D7)=1,"",(_xlfn.XLOOKUP(D7,BS_CONSOLIDADO!A:A,BS_CONSOLIDADO!H:H,""))-(_xlfn.XLOOKUP(D7,BS_SIMULADOR!A:A,BS_SIMULADOR!H:H,"")))*(-1),"") | V7: =IFERROR(IF(COUNTBLANK(D7)=1,"",(_xlfn.XLOOKUP(D7,BS_CONSOLIDADO!A:A,BS_CONSOLIDADO!J:J,""))-(_xlfn.XLOOKUP(D7,BS_SIMULADOR!A:A,BS_SIMULADOR!J:J,"")))*(-1),"") | W7: =IFERROR(IF(COUNTBLANK($D7)=1,"",(_xlfn.XLOOKUP($D7,BS_CONSOLIDADO!$A:$A,BS_CONSOLIDADO!L:L,""))-(_xlfn.XLOOKUP($D7,BS_SIMULADOR!$A:$A,BS_SIMULADOR!L:L,"")))*(-1),"")
A8: Parceiro 3 | E8: =IF(COUNTBLANK(D8)=1,"",_xlfn.XLOOKUP(D8,BS_CONSOLIDADO!A:A,BS_CONSOLIDADO!D:D,"")) | F8: =IF(COUNTBLANK(D8)=1,"",_xlfn.XLOOKUP(D8,BS_CONSOLIDADO!A:A,BS_CONSOLIDADO!Q:Q,"")) | G8: =IF(COUNTBLANK($D8)=1,"",_xlfn.XLOOKUP($D8,BS_CONSOLIDADO!$A:$A,BS_CONSOLIDADO!M:M,"")) | H8: =IF(COUNTBLANK(D8)=1,"",_xlfn.XLOOKUP(D8,BS_CONSOLIDADO!A:A,BS_CONSOLIDADO!N:N,"")) | I8: =IF(COUNTBLANK(D8)=1,"",_xlfn.XLOOKUP(D8,BS_CONSOLIDADO!A:A,BS_CONSOLIDADO!O:O,"")) | J8: =IF(COUNTBLANK(D8)=1,"",_xlfn.XLOOKUP(D8,BS_CONSOLIDADO!A:A,BS_CONSOLIDADO!P:P,"")) | L8: =IF(COUNTBLANK(D8)=1,"",_xlfn.XLOOKUP(D8,BS_SIMULADOR!A:A,BS_SIMULADOR!D:D,"")) | M8: =IF(COUNTBLANK(D8)=1,"",_xlfn.XLOOKUP(D8,BS_SIMULADOR!A:A,BS_SIMULADOR!Q:Q,"")) | N8: =IF(COUNTBLANK($D8)=1,"",_xlfn.XLOOKUP($D8,BS_SIMULADOR!$A:$A,BS_SIMULADOR!M:M,"")) | O8: =IF(COUNTBLANK(D8)=1,"",_xlfn.XLOOKUP(D8,BS_SIMULADOR!A:A,BS_SIMULADOR!N:N,"")) | P8: =IF(COUNTBLANK(D8)=1,"",_xlfn.XLOOKUP(D8,BS_SIMULADOR!A:A,BS_SIMULADOR!O:O,"")) | Q8: =IF(COUNTBLANK($D8)=1,"",_xlfn.XLOOKUP($D8,BS_SIMULADOR!$A:$A,BS_SIMULADOR!P:P,"")) | S8: =IFERROR(IF(COUNTBLANK(D8)=1,"",E8-L8)*(-1),"") | T8: =IFERROR(IF(COUNTBLANK($D8)=1,"",(_xlfn.XLOOKUP($D8,BS_CONSOLIDADO!$A:$A,BS_CONSOLIDADO!F:F,""))-(_xlfn.XLOOKUP($D8,BS_SIMULADOR!$A:$A,BS_SIMULADOR!F:F,"")))*(-1),"") | U8: =IFERROR(IF(COUNTBLANK(D8)=1,"",(_xlfn.XLOOKUP(D8,BS_CONSOLIDADO!A:A,BS_CONSOLIDADO!H:H,""))-(_xlfn.XLOOKUP(D8,BS_SIMULADOR!A:A,BS_SIMULADOR!H:H,"")))*(-1),"") | V8: =IFERROR(IF(COUNTBLANK(D8)=1,"",(_xlfn.XLOOKUP(D8,BS_CONSOLIDADO!A:A,BS_CONSOLIDADO!J:J,""))-(_xlfn.XLOOKUP(D8,BS_SIMULADOR!A:A,BS_SIMULADOR!J:J,"")))*(-1),"") | W8: =IFERROR(IF(COUNTBLANK($D8)=1,"",(_xlfn.XLOOKUP($D8,BS_CONSOLIDADO!$A:$A,BS_CONSOLIDADO!L:L,""))-(_xlfn.XLOOKUP($D8,BS_SIMULADOR!$A:$A,BS_SIMULADOR!L:L,"")))*(-1),"")
A9: Parceiro 4 | E9: =IF(COUNTBLANK(D9)=1,"",_xlfn.XLOOKUP(D9,BS_CONSOLIDADO!A:A,BS_CONSOLIDADO!D:D,"")) | F9: =IF(COUNTBLANK(D9)=1,"",_xlfn.XLOOKUP(D9,BS_CONSOLIDADO!A:A,BS_CONSOLIDADO!Q:Q,"")) | G9: =IF(COUNTBLANK($D9)=1,"",_xlfn.XLOOKUP($D9,BS_CONSOLIDADO!$A:$A,BS_CONSOLIDADO!M:M,"")) | H9: =IF(COUNTBLANK(D9)=1,"",_xlfn.XLOOKUP(D9,BS_CONSOLIDADO!A:A,BS_CONSOLIDADO!N:N,"")) | I9: =IF(COUNTBLANK(D9)=1,"",_xlfn.XLOOKUP(D9,BS_CONSOLIDADO!A:A,BS_CONSOLIDADO!O:O,"")) | J9: =IF(COUNTBLANK(D9)=1,"",_xlfn.XLOOKUP(D9,BS_CONSOLIDADO!A:A,BS_CONSOLIDADO!P:P,"")) | L9: =IF(COUNTBLANK(D9)=1,"",_xlfn.XLOOKUP(D9,BS_SIMULADOR!A:A,BS_SIMULADOR!D:D,"")) | M9: =IF(COUNTBLANK(D9)=1,"",_xlfn.XLOOKUP(D9,BS_SIMULADOR!A:A,BS_SIMULADOR!Q:Q,"")) | N9: =IF(COUNTBLANK($D9)=1,"",_xlfn.XLOOKUP($D9,BS_SIMULADOR!$A:$A,BS_SIMULADOR!M:M,"")) | O9: =IF(COUNTBLANK(D9)=1,"",_xlfn.XLOOKUP(D9,BS_SIMULADOR!A:A,BS_SIMULADOR!N:N,"")) | P9: =IF(COUNTBLANK(D9)=1,"",_xlfn.XLOOKUP(D9,BS_SIMULADOR!A:A,BS_SIMULADOR!O:O,"")) | Q9: =IF(COUNTBLANK($D9)=1,"",_xlfn.XLOOKUP($D9,BS_SIMULADOR!$A:$A,BS_SIMULADOR!P:P,"")) | S9: =IFERROR(IF(COUNTBLANK(D9)=1,"",E9-L9)*(-1),"") | T9: =IFERROR(IF(COUNTBLANK($D9)=1,"",(_xlfn.XLOOKUP($D9,BS_CONSOLIDADO!$A:$A,BS_CONSOLIDADO!F:F,""))-(_xlfn.XLOOKUP($D9,BS_SIMULADOR!$A:$A,BS_SIMULADOR!F:F,"")))*(-1),"") | U9: =IFERROR(IF(COUNTBLANK(D9)=1,"",(_xlfn.XLOOKUP(D9,BS_CONSOLIDADO!A:A,BS_CONSOLIDADO!H:H,""))-(_xlfn.XLOOKUP(D9,BS_SIMULADOR!A:A,BS_SIMULADOR!H:H,"")))*(-1),"") | V9: =IFERROR(IF(COUNTBLANK(D9)=1,"",(_xlfn.XLOOKUP(D9,BS_CONSOLIDADO!A:A,BS_CONSOLIDADO!J:J,""))-(_xlfn.XLOOKUP(D9,BS_SIMULADOR!A:A,BS_SIMULADOR!J:J,"")))*(-1),"") | W9: =IFERROR(IF(COUNTBLANK($D9)=1,"",(_xlfn.XLOOKUP($D9,BS_CONSOLIDADO!$A:$A,BS_CONSOLIDADO!L:L,""))-(_xlfn.XLOOKUP($D9,BS_SIMULADOR!$A:$A,BS_SIMULADOR!L:L,"")))*(-1),"")
A10: Parceiro 5 | E10: =IF(COUNTBLANK(D10)=1,"",_xlfn.XLOOKUP(D10,BS_CONSOLIDADO!A:A,BS_CONSOLIDADO!D:D,"")) | F10: =IF(COUNTBLANK(D10)=1,"",_xlfn.XLOOKUP(D10,BS_CONSOLIDADO!A:A,BS_CONSOLIDADO!Q:Q,"")) | G10: =IF(COUNTBLANK($D10)=1,"",_xlfn.XLOOKUP($D10,BS_CONSOLIDADO!$A:$A,BS_CONSOLIDADO!M:M,"")) | H10: =IF(COUNTBLANK(D10)=1,"",_xlfn.XLOOKUP(D10,BS_CONSOLIDADO!A:A,BS_CONSOLIDADO!N:N,"")) | I10: =IF(COUNTBLANK(D10)=1,"",_xlfn.XLOOKUP(D10,BS_CONSOLIDADO!A:A,BS_CONSOLIDADO!O:O,"")) | J10: =IF(COUNTBLANK(D10)=1,"",_xlfn.XLOOKUP(D10,BS_CONSOLIDADO!A:A,BS_CONSOLIDADO!P:P,"")) | L10: =IF(COUNTBLANK(D10)=1,"",_xlfn.XLOOKUP(D10,BS_SIMULADOR!A:A,BS_SIMULADOR!D:D,"")) | M10: =IF(COUNTBLANK(D10)=1,"",_xlfn.XLOOKUP(D10,BS_SIMULADOR!A:A,BS_SIMULADOR!Q:Q,"")) | N10: =IF(COUNTBLANK($D10)=1,"",_xlfn.XLOOKUP($D10,BS_SIMULADOR!$A:$A,BS_SIMULADOR!M:M,"")) | O10: =IF(COUNTBLANK(D10)=1,"",_xlfn.XLOOKUP(D10,BS_SIMULADOR!A:A,BS_SIMULADOR!N:N,"")) | P10: =IF(COUNTBLANK(D10)=1,"",_xlfn.XLOOKUP(D10,BS_SIMULADOR!A:A,BS_SIMULADOR!O:O,"")) | Q10: =IF(COUNTBLANK($D10)=1,"",_xlfn.XLOOKUP($D10,BS_SIMULADOR!$A:$A,BS_SIMULADOR!P:P,"")) | S10: =IFERROR(IF(COUNTBLANK(D10)=1,"",E10-L10)*(-1),"") | T10: =IFERROR(IF(COUNTBLANK($D10)=1,"",(_xlfn.XLOOKUP($D10,BS_CONSOLIDADO!$A:$A,BS_CONSOLIDADO!F:F,""))-(_xlfn.XLOOKUP($D10,BS_SIMULADOR!$A:$A,BS_SIMULADOR!F:F,"")))*(-1),"") | U10: =IFERROR(IF(COUNTBLANK(D10)=1,"",(_xlfn.XLOOKUP(D10,BS_CONSOLIDADO!A:A,BS_CONSOLIDADO!H:H,""))-(_xlfn.XLOOKUP(D10,BS_SIMULADOR!A:A,BS_SIMULADOR!H:H,"")))*(-1),"") | V10: =IFERROR(IF(COUNTBLANK(D10)=1,"",(_xlfn.XLOOKUP(D10,BS_CONSOLIDADO!A:A,BS_CONSOLIDADO!J:J,""))-(_xlfn.XLOOKUP(D10,BS_SIMULADOR!A:A,BS_SIMULADOR!J:J,"")))*(-1),"") | W10: =IFERROR(IF(COUNTBLANK($D10)=1,"",(_xlfn.XLOOKUP($D10,BS_CONSOLIDADO!$A:$A,BS_CONSOLIDADO!L:L,""))-(_xlfn.XLOOKUP($D10,BS_SIMULADOR!$A:$A,BS_SIMULADOR!L:L,"")))*(-1),"")
A11: Parceiro 6 | E11: =IF(COUNTBLANK(D11)=1,"",_xlfn.XLOOKUP(D11,BS_CONSOLIDADO!A:A,BS_CONSOLIDADO!D:D,"")) | F11: =IF(COUNTBLANK(D11)=1,"",_xlfn.XLOOKUP(D11,BS_CONSOLIDADO!A:A,BS_CONSOLIDADO!Q:Q,"")) | G11: =IF(COUNTBLANK($D11)=1,"",_xlfn.XLOOKUP($D11,BS_CONSOLIDADO!$A:$A,BS_CONSOLIDADO!M:M,"")) | H11: =IF(COUNTBLANK(D11)=1,"",_xlfn.XLOOKUP(D11,BS_CONSOLIDADO!A:A,BS_CONSOLIDADO!N:N,"")) | I11: =IF(COUNTBLANK(D11)=1,"",_xlfn.XLOOKUP(D11,BS_CONSOLIDADO!A:A,BS_CONSOLIDADO!O:O,"")) | J11: =IF(COUNTBLANK(D11)=1,"",_xlfn.XLOOKUP(D11,BS_CONSOLIDADO!A:A,BS_CONSOLIDADO!P:P,"")) | L11: =IF(COUNTBLANK(D11)=1,"",_xlfn.XLOOKUP(D11,BS_SIMULADOR!A:A,BS_SIMULADOR!D:D,"")) | M11: =IF(COUNTBLANK(D11)=1,"",_xlfn.XLOOKUP(D11,BS_SIMULADOR!A:A,BS_SIMULADOR!Q:Q,"")) | N11: =IF(COUNTBLANK($D11)=1,"",_xlfn.XLOOKUP($D11,BS_SIMULADOR!$A:$A,BS_SIMULADOR!M:M,"")) | O11: =IF(COUNTBLANK(D11)=1,"",_xlfn.XLOOKUP(D11,BS_SIMULADOR!A:A,BS_SIMULADOR!N:N,"")) | P11: =IF(COUNTBLANK(D11)=1,"",_xlfn.XLOOKUP(D11,BS_SIMULADOR!A:A,BS_SIMULADOR!O:O,"")) | Q11: =IF(COUNTBLANK($D11)=1,"",_xlfn.XLOOKUP($D11,BS_SIMULADOR!$A:$A,BS_SIMULADOR!P:P,"")) | S11: =IFERROR(IF(COUNTBLANK(D11)=1,"",E11-L11)*(-1),"") | T11: =IFERROR(IF(COUNTBLANK($D11)=1,"",(_xlfn.XLOOKUP($D11,BS_CONSOLIDADO!$A:$A,BS_CONSOLIDADO!F:F,""))-(_xlfn.XLOOKUP($D11,BS_SIMULADOR!$A:$A,BS_SIMULADOR!F:F,"")))*(-1),"") | U11: =IFERROR(IF(COUNTBLANK(D11)=1,"",(_xlfn.XLOOKUP(D11,BS_CONSOLIDADO!A:A,BS_CONSOLIDADO!H:H,""))-(_xlfn.XLOOKUP(D11,BS_SIMULADOR!A:A,BS_SIMULADOR!H:H,"")))*(-1),"") | V11: =IFERROR(IF(COUNTBLANK(D11)=1,"",(_xlfn.XLOOKUP(D11,BS_CONSOLIDADO!A:A,BS_CONSOLIDADO!J:J,""))-(_xlfn.XLOOKUP(D11,BS_SIMULADOR!A:A,BS_SIMULADOR!J:J,"")))*(-1),"") | W11: =IFERROR(IF(COUNTBLANK($D11)=1,"",(_xlfn.XLOOKUP($D11,BS_CONSOLIDADO!$A:$A,BS_CONSOLIDADO!L:L,""))-(_xlfn.XLOOKUP($D11,BS_SIMULADOR!$A:$A,BS_SIMULADOR!L:L,"")))*(-1),"")
A12: Parceiro 7 | E12: =IF(COUNTBLANK(D12)=1,"",_xlfn.XLOOKUP(D12,BS_CONSOLIDADO!A:A,BS_CONSOLIDADO!D:D,"")) | F12: =IF(COUNTBLANK(D12)=1,"",_xlfn.XLOOKUP(D12,BS_CONSOLIDADO!A:A,BS_CONSOLIDADO!Q:Q,"")) | G12: =IF(COUNTBLANK($D12)=1,"",_xlfn.XLOOKUP($D12,BS_CONSOLIDADO!$A:$A,BS_CONSOLIDADO!M:M,"")) | H12: =IF(COUNTBLANK(D12)=1,"",_xlfn.XLOOKUP(D12,BS_CONSOLIDADO!A:A,BS_CONSOLIDADO!N:N,"")) | I12: =IF(COUNTBLANK(D12)=1,"",_xlfn.XLOOKUP(D12,BS_CONSOLIDADO!A:A,BS_CONSOLIDADO!O:O,"")) | J12: =IF(COUNTBLANK(D12)=1,"",_xlfn.XLOOKUP(D12,BS_CONSOLIDADO!A:A,BS_CONSOLIDADO!P:P,"")) | L12: =IF(COUNTBLANK(D12)=1,"",_xlfn.XLOOKUP(D12,BS_SIMULADOR!A:A,BS_SIMULADOR!D:D,"")) | M12: =IF(COUNTBLANK(D12)=1,"",_xlfn.XLOOKUP(D12,BS_SIMULADOR!A:A,BS_SIMULADOR!Q:Q,"")) | N12: =IF(COUNTBLANK($D12)=1,"",_xlfn.XLOOKUP($D12,BS_SIMULADOR!$A:$A,BS_SIMULADOR!M:M,"")) | O12: =IF(COUNTBLANK(D12)=1,"",_xlfn.XLOOKUP(D12,BS_SIMULADOR!A:A,BS_SIMULADOR!N:N,"")) | P12: =IF(COUNTBLANK(D12)=1,"",_xlfn.XLOOKUP(D12,BS_SIMULADOR!A:A,BS_SIMULADOR!O:O,"")) | Q12: =IF(COUNTBLANK($D12)=1,"",_xlfn.XLOOKUP($D12,BS_SIMULADOR!$A:$A,BS_SIMULADOR!P:P,"")) | S12: =IFERROR(IF(COUNTBLANK(D12)=1,"",E12-L12)*(-1),"") | T12: =IFERROR(IF(COUNTBLANK($D12)=1,"",(_xlfn.XLOOKUP($D12,BS_CONSOLIDADO!$A:$A,BS_CONSOLIDADO!F:F,""))-(_xlfn.XLOOKUP($D12,BS_SIMULADOR!$A:$A,BS_SIMULADOR!F:F,"")))*(-1),"") | U12: =IFERROR(IF(COUNTBLANK(D12)=1,"",(_xlfn.XLOOKUP(D12,BS_CONSOLIDADO!A:A,BS_CONSOLIDADO!H:H,""))-(_xlfn.XLOOKUP(D12,BS_SIMULADOR!A:A,BS_SIMULADOR!H:H,"")))*(-1),"") | V12: =IFERROR(IF(COUNTBLANK(D12)=1,"",(_xlfn.XLOOKUP(D12,BS_CONSOLIDADO!A:A,BS_CONSOLIDADO!J:J,""))-(_xlfn.XLOOKUP(D12,BS_SIMULADOR!A:A,BS_SIMULADOR!J:J,"")))*(-1),"") | W12: =IFERROR(IF(COUNTBLANK($D12)=1,"",(_xlfn.XLOOKUP($D12,BS_CONSOLIDADO!$A:$A,BS_CONSOLIDADO!L:L,""))-(_xlfn.XLOOKUP($D12,BS_SIMULADOR!$A:$A,BS_SIMULADOR!L:L,"")))*(-1),"")
A13: Parceiro 8 | E13: =IF(COUNTBLANK(D13)=1,"",_xlfn.XLOOKUP(D13,BS_CONSOLIDADO!A:A,BS_CONSOLIDADO!D:D,"")) | F13: =IF(COUNTBLANK(D13)=1,"",_xlfn.XLOOKUP(D13,BS_CONSOLIDADO!A:A,BS_CONSOLIDADO!Q:Q,"")) | G13: =IF(COUNTBLANK($D13)=1,"",_xlfn.XLOOKUP($D13,BS_CONSOLIDADO!$A:$A,BS_CONSOLIDADO!M:M,"")) | H13: =IF(COUNTBLANK(D13)=1,"",_xlfn.XLOOKUP(D13,BS_CONSOLIDADO!A:A,BS_CONSOLIDADO!N:N,"")) | I13: =IF(COUNTBLANK(D13)=1,"",_xlfn.XLOOKUP(D13,BS_CONSOLIDADO!A:A,BS_CONSOLIDADO!O:O,"")) | J13: =IF(COUNTBLANK(D13)=1,"",_xlfn.XLOOKUP(D13,BS_CONSOLIDADO!A:A,BS_CONSOLIDADO!P:P,"")) | L13: =IF(COUNTBLANK(D13)=1,"",_xlfn.XLOOKUP(D13,BS_SIMULADOR!A:A,BS_SIMULADOR!D:D,"")) | M13: =IF(COUNTBLANK(D13)=1,"",_xlfn.XLOOKUP(D13,BS_SIMULADOR!A:A,BS_SIMULADOR!Q:Q,"")) | N13: =IF(COUNTBLANK($D13)=1,"",_xlfn.XLOOKUP($D13,BS_SIMULADOR!$A:$A,BS_SIMULADOR!M:M,"")) | O13: =IF(COUNTBLANK(D13)=1,"",_xlfn.XLOOKUP(D13,BS_SIMULADOR!A:A,BS_SIMULADOR!N:N,"")) | P13: =IF(COUNTBLANK(D13)=1,"",_xlfn.XLOOKUP(D13,BS_SIMULADOR!A:A,BS_SIMULADOR!O:O,"")) | Q13: =IF(COUNTBLANK($D13)=1,"",_xlfn.XLOOKUP($D13,BS_SIMULADOR!$A:$A,BS_SIMULADOR!P:P,"")) | S13: =IFERROR(IF(COUNTBLANK(D13)=1,"",E13-L13)*(-1),"") | T13: =IFERROR(IF(COUNTBLANK($D13)=1,"",(_xlfn.XLOOKUP($D13,BS_CONSOLIDADO!$A:$A,BS_CONSOLIDADO!F:F,""))-(_xlfn.XLOOKUP($D13,BS_SIMULADOR!$A:$A,BS_SIMULADOR!F:F,"")))*(-1),"") | U13: =IFERROR(IF(COUNTBLANK(D13)=1,"",(_xlfn.XLOOKUP(D13,BS_CONSOLIDADO!A:A,BS_CONSOLIDADO!H:H,""))-(_xlfn.XLOOKUP(D13,BS_SIMULADOR!A:A,BS_SIMULADOR!H:H,"")))*(-1),"") | V13: =IFERROR(IF(COUNTBLANK(D13)=1,"",(_xlfn.XLOOKUP(D13,BS_CONSOLIDADO!A:A,BS_CONSOLIDADO!J:J,""))-(_xlfn.XLOOKUP(D13,BS_SIMULADOR!A:A,BS_SIMULADOR!J:J,"")))*(-1),"") | W13: =IFERROR(IF(COUNTBLANK($D13)=1,"",(_xlfn.XLOOKUP($D13,BS_CONSOLIDADO!$A:$A,BS_CONSOLIDADO!L:L,""))-(_xlfn.XLOOKUP($D13,BS_SIMULADOR!$A:$A,BS_SIMULADOR!L:L,"")))*(-1),"")
A14: Parceiro 9 | E14: =IF(COUNTBLANK(D14)=1,"",_xlfn.XLOOKUP(D14,BS_CONSOLIDADO!A:A,BS_CONSOLIDADO!D:D,"")) | F14: =IF(COUNTBLANK(D14)=1,"",_xlfn.XLOOKUP(D14,BS_CONSOLIDADO!A:A,BS_CONSOLIDADO!Q:Q,"")) | G14: =IF(COUNTBLANK($D14)=1,"",_xlfn.XLOOKUP($D14,BS_CONSOLIDADO!$A:$A,BS_CONSOLIDADO!M:M,"")) | H14: =IF(COUNTBLANK(D14)=1,"",_xlfn.XLOOKUP(D14,BS_CONSOLIDADO!A:A,BS_CONSOLIDADO!N:N,"")) | I14: =IF(COUNTBLANK(D14)=1,"",_xlfn.XLOOKUP(D14,BS_CONSOLIDADO!A:A,BS_CONSOLIDADO!O:O,"")) | J14: =IF(COUNTBLANK(D14)=1,"",_xlfn.XLOOKUP(D14,BS_CONSOLIDADO!A:A,BS_CONSOLIDADO!P:P,"")) | L14: =IF(COUNTBLANK(D14)=1,"",_xlfn.XLOOKUP(D14,BS_SIMULADOR!A:A,BS_SIMULADOR!D:D,"")) | M14: =IF(COUNTBLANK(D14)=1,"",_xlfn.XLOOKUP(D14,BS_SIMULADOR!A:A,BS_SIMULADOR!Q:Q,"")) | N14: =IF(COUNTBLANK($D14)=1,"",_xlfn.XLOOKUP($D14,BS_SIMULADOR!$A:$A,BS_SIMULADOR!M:M,"")) | O14: =IF(COUNTBLANK(D14)=1,"",_xlfn.XLOOKUP(D14,BS_SIMULADOR!A:A,BS_SIMULADOR!N:N,"")) | P14: =IF(COUNTBLANK(D14)=1,"",_xlfn.XLOOKUP(D14,BS_SIMULADOR!A:A,BS_SIMULADOR!O:O,"")) | Q14: =IF(COUNTBLANK($D14)=1,"",_xlfn.XLOOKUP($D14,BS_SIMULADOR!$A:$A,BS_SIMULADOR!P:P,"")) | S14: =IFERROR(IF(COUNTBLANK(D14)=1,"",E14-L14)*(-1),"") | T14: =IFERROR(IF(COUNTBLANK($D14)=1,"",(_xlfn.XLOOKUP($D14,BS_CONSOLIDADO!$A:$A,BS_CONSOLIDADO!F:F,""))-(_xlfn.XLOOKUP($D14,BS_SIMULADOR!$A:$A,BS_SIMULADOR!F:F,"")))*(-1),"") | U14: =IFERROR(IF(COUNTBLANK(D14)=1,"",(_xlfn.XLOOKUP(D14,BS_CONSOLIDADO!A:A,BS_CONSOLIDADO!H:H,""))-(_xlfn.XLOOKUP(D14,BS_SIMULADOR!A:A,BS_SIMULADOR!H:H,"")))*(-1),"") | V14: =IFERROR(IF(COUNTBLANK(D14)=1,"",(_xlfn.XLOOKUP(D14,BS_CONSOLIDADO!A:A,BS_CONSOLIDADO!J:J,""))-(_xlfn.XLOOKUP(D14,BS_SIMULADOR!A:A,BS_SIMULADOR!J:J,"")))*(-1),"") | W14: =IFERROR(IF(COUNTBLANK($D14)=1,"",(_xlfn.XLOOKUP($D14,BS_CONSOLIDADO!$A:$A,BS_CONSOLIDADO!L:L,""))-(_xlfn.XLOOKUP($D14,BS_SIMULADOR!$A:$A,BS_SIMULADOR!L:L,"")))*(-1),"")
A15: Parceiro 10 | E15: =IF(COUNTBLANK(D15)=1,"",_xlfn.XLOOKUP(D15,BS_CONSOLIDADO!A:A,BS_CONSOLIDADO!D:D,"")) | F15: =IF(COUNTBLANK(D15)=1,"",_xlfn.XLOOKUP(D15,BS_CONSOLIDADO!A:A,BS_CONSOLIDADO!Q:Q,"")) | G15: =IF(COUNTBLANK($D15)=1,"",_xlfn.XLOOKUP($D15,BS_CONSOLIDADO!$A:$A,BS_CONSOLIDADO!M:M,"")) | H15: =IF(COUNTBLANK(D15)=1,"",_xlfn.XLOOKUP(D15,BS_CONSOLIDADO!A:A,BS_CONSOLIDADO!N:N,"")) | I15: =IF(COUNTBLANK(D15)=1,"",_xlfn.XLOOKUP(D15,BS_CONSOLIDADO!A:A,BS_CONSOLIDADO!O:O,"")) | J15: =IF(COUNTBLANK(D15)=1,"",_xlfn.XLOOKUP(D15,BS_CONSOLIDADO!A:A,BS_CONSOLIDADO!P:P,"")) | L15: =IF(COUNTBLANK(D15)=1,"",_xlfn.XLOOKUP(D15,BS_SIMULADOR!A:A,BS_SIMULADOR!D:D,"")) | M15: =IF(COUNTBLANK(D15)=1,"",_xlfn.XLOOKUP(D15,BS_SIMULADOR!A:A,BS_SIMULADOR!Q:Q,"")) | N15: =IF(COUNTBLANK($D15)=1,"",_xlfn.XLOOKUP($D15,BS_SIMULADOR!$A:$A,BS_SIMULADOR!M:M,"")) | O15: =IF(COUNTBLANK(D15)=1,"",_xlfn.XLOOKUP(D15,BS_SIMULADOR!A:A,BS_SIMULADOR!N:N,"")) | P15: =IF(COUNTBLANK(D15)=1,"",_xlfn.XLOOKUP(D15,BS_SIMULADOR!A:A,BS_SIMULADOR!O:O,"")) | Q15: =IF(COUNTBLANK($D15)=1,"",_xlfn.XLOOKUP($D15,BS_SIMULADOR!$A:$A,BS_SIMULADOR!P:P,"")) | S15: =IFERROR(IF(COUNTBLANK(D15)=1,"",E15-L15)*(-1),"") | T15: =IFERROR(IF(COUNTBLANK($D15)=1,"",(_xlfn.XLOOKUP($D15,BS_CONSOLIDADO!$A:$A,BS_CONSOLIDADO!F:F,""))-(_xlfn.XLOOKUP($D15,BS_SIMULADOR!$A:$A,BS_SIMULADOR!F:F,"")))*(-1),"") | U15: =IFERROR(IF(COUNTBLANK(D15)=1,"",(_xlfn.XLOOKUP(D15,BS_CONSOLIDADO!A:A,BS_CONSOLIDADO!H:H,""))-(_xlfn.XLOOKUP(D15,BS_SIMULADOR!A:A,BS_SIMULADOR!H:H,"")))*(-1),"") | V15: =IFERROR(IF(COUNTBLANK(D15)=1,"",(_xlfn.XLOOKUP(D15,BS_CONSOLIDADO!A:A,BS_CONSOLIDADO!J:J,""))-(_xlfn.XLOOKUP(D15,BS_SIMULADOR!A:A,BS_SIMULADOR!J:J,"")))*(-1),"") | W15: =IFERROR(IF(COUNTBLANK($D15)=1,"",(_xlfn.XLOOKUP($D15,BS_CONSOLIDADO!$A:$A,BS_CONSOLIDADO!L:L,""))-(_xlfn.XLOOKUP($D15,BS_SIMULADOR!$A:$A,BS_SIMULADOR!L:L,"")))*(-1),"")
A16: Parceiro 11 | E16: =IF(COUNTBLANK(D16)=1,"",_xlfn.XLOOKUP(D16,BS_CONSOLIDADO!A:A,BS_CONSOLIDADO!D:D,"")) | F16: =IF(COUNTBLANK(D16)=1,"",_xlfn.XLOOKUP(D16,BS_CONSOLIDADO!A:A,BS_CONSOLIDADO!Q:Q,"")) | G16: =IF(COUNTBLANK($D16)=1,"",_xlfn.XLOOKUP($D16,BS_CONSOLIDADO!$A:$A,BS_CONSOLIDADO!M:M,"")) | H16: =IF(COUNTBLANK(D16)=1,"",_xlfn.XLOOKUP(D16,BS_CONSOLIDADO!A:A,BS_CONSOLIDADO!N:N,"")) | I16: =IF(COUNTBLANK(D16)=1,"",_xlfn.XLOOKUP(D16,BS_CONSOLIDADO!A:A,BS_CONSOLIDADO!O:O,"")) | J16: =IF(COUNTBLANK(D16)=1,"",_xlfn.XLOOKUP(D16,BS_CONSOLIDADO!A:A,BS_CONSOLIDADO!P:P,"")) | L16: =IF(COUNTBLANK(D16)=1,"",_xlfn.XLOOKUP(D16,BS_SIMULADOR!A:A,BS_SIMULADOR!D:D,"")) | M16: =IF(COUNTBLANK(D16)=1,"",_xlfn.XLOOKUP(D16,BS_SIMULADOR!A:A,BS_SIMULADOR!Q:Q,"")) | N16: =IF(COUNTBLANK($D16)=1,"",_xlfn.XLOOKUP($D16,BS_SIMULADOR!$A:$A,BS_SIMULADOR!M:M,"")) | O16: =IF(COUNTBLANK(D16)=1,"",_xlfn.XLOOKUP(D16,BS_SIMULADOR!A:A,BS_SIMULADOR!N:N,"")) | P16: =IF(COUNTBLANK(D16)=1,"",_xlfn.XLOOKUP(D16,BS_SIMULADOR!A:A,BS_SIMULADOR!O:O,"")) | Q16: =IF(COUNTBLANK($D16)=1,"",_xlfn.XLOOKUP($D16,BS_SIMULADOR!$A:$A,BS_SIMULADOR!P:P,"")) | S16: =IFERROR(IF(COUNTBLANK(D16)=1,"",E16-L16)*(-1),"") | T16: =IFERROR(IF(COUNTBLANK($D16)=1,"",(_xlfn.XLOOKUP($D16,BS_CONSOLIDADO!$A:$A,BS_CONSOLIDADO!F:F,""))-(_xlfn.XLOOKUP($D16,BS_SIMULADOR!$A:$A,BS_SIMULADOR!F:F,"")))*(-1),"") | U16: =IFERROR(IF(COUNTBLANK(D16)=1,"",(_xlfn.XLOOKUP(D16,BS_CONSOLIDADO!A:A,BS_CONSOLIDADO!H:H,""))-(_xlfn.XLOOKUP(D16,BS_SIMULADOR!A:A,BS_SIMULADOR!H:H,"")))*(-1),"") | V16: =IFERROR(IF(COUNTBLANK(D16)=1,"",(_xlfn.XLOOKUP(D16,BS_CONSOLIDADO!A:A,BS_CONSOLIDADO!J:J,""))-(_xlfn.XLOOKUP(D16,BS_SIMULADOR!A:A,BS_SIMULADOR!J:J,"")))*(-1),"") | W16: =IFERROR(IF(COUNTBLANK($D16)=1,"",(_xlfn.XLOOKUP($D16,BS_CONSOLIDADO!$A:$A,BS_CONSOLIDADO!L:L,""))-(_xlfn.XLOOKUP($D16,BS_SIMULADOR!$A:$A,BS_SIMULADOR!L:L,"")))*(-1),"")
A17: Parceiro 12 | E17: =IF(COUNTBLANK(D17)=1,"",_xlfn.XLOOKUP(D17,BS_CONSOLIDADO!A:A,BS_CONSOLIDADO!D:D,"")) | F17: =IF(COUNTBLANK(D17)=1,"",_xlfn.XLOOKUP(D17,BS_CONSOLIDADO!A:A,BS_CONSOLIDADO!Q:Q,"")) | G17: =IF(COUNTBLANK($D17)=1,"",_xlfn.XLOOKUP($D17,BS_CONSOLIDADO!$A:$A,BS_CONSOLIDADO!M:M,"")) | H17: =IF(COUNTBLANK(D17)=1,"",_xlfn.XLOOKUP(D17,BS_CONSOLIDADO!A:A,BS_CONSOLIDADO!N:N,"")) | I17: =IF(COUNTBLANK(D17)=1,"",_xlfn.XLOOKUP(D17,BS_CONSOLIDADO!A:A,BS_CONSOLIDADO!O:O,"")) | J17: =IF(COUNTBLANK(D17)=1,"",_xlfn.XLOOKUP(D17,BS_CONSOLIDADO!A:A,BS_CONSOLIDADO!P:P,"")) | L17: =IF(COUNTBLANK(D17)=1,"",_xlfn.XLOOKUP(D17,BS_SIMULADOR!A:A,BS_SIMULADOR!D:D,"")) | M17: =IF(COUNTBLANK(D17)=1,"",_xlfn.XLOOKUP(D17,BS_SIMULADOR!A:A,BS_SIMULADOR!Q:Q,"")) | N17: =IF(COUNTBLANK($D17)=1,"",_xlfn.XLOOKUP($D17,BS_SIMULADOR!$A:$A,BS_SIMULADOR!M:M,"")) | O17: =IF(COUNTBLANK(D17)=1,"",_xlfn.XLOOKUP(D17,BS_SIMULADOR!A:A,BS_SIMULADOR!N:N,"")) | P17: =IF(COUNTBLANK(D17)=1,"",_xlfn.XLOOKUP(D17,BS_SIMULADOR!A:A,BS_SIMULADOR!O:O,"")) | Q17: =IF(COUNTBLANK($D17)=1,"",_xlfn.XLOOKUP($D17,BS_SIMULADOR!$A:$A,BS_SIMULADOR!P:P,"")) | S17: =IFERROR(IF(COUNTBLANK(D17)=1,"",E17-L17)*(-1),"") | T17: =IFERROR(IF(COUNTBLANK($D17)=1,"",(_xlfn.XLOOKUP($D17,BS_CONSOLIDADO!$A:$A,BS_CONSOLIDADO!F:F,""))-(_xlfn.XLOOKUP($D17,BS_SIMULADOR!$A:$A,BS_SIMULADOR!F:F,"")))*(-1),"") | U17: =IFERROR(IF(COUNTBLANK(D17)=1,"",(_xlfn.XLOOKUP(D17,BS_CONSOLIDADO!A:A,BS_CONSOLIDADO!H:H,""))-(_xlfn.XLOOKUP(D17,BS_SIMULADOR!A:A,BS_SIMULADOR!H:H,"")))*(-1),"") | V17: =IFERROR(IF(COUNTBLANK(D17)=1,"",(_xlfn.XLOOKUP(D17,BS_CONSOLIDADO!A:A,BS_CONSOLIDADO!J:J,""))-(_xlfn.XLOOKUP(D17,BS_SIMULADOR!A:A,BS_SIMULADOR!J:J,"")))*(-1),"") | W17: =IFERROR(IF(COUNTBLANK($D17)=1,"",(_xlfn.XLOOKUP($D17,BS_CONSOLIDADO!$A:$A,BS_CONSOLIDADO!L:L,""))-(_xlfn.XLOOKUP($D17,BS_SIMULADOR!$A:$A,BS_SIMULADOR!L:L,"")))*(-1),"")
A18: Parceiro 13 | E18: =IF(COUNTBLANK(D18)=1,"",_xlfn.XLOOKUP(D18,BS_CONSOLIDADO!A:A,BS_CONSOLIDADO!D:D,"")) | F18: =IF(COUNTBLANK(D18)=1,"",_xlfn.XLOOKUP(D18,BS_CONSOLIDADO!A:A,BS_CONSOLIDADO!Q:Q,"")) | G18: =IF(COUNTBLANK($D18)=1,"",_xlfn.XLOOKUP($D18,BS_CONSOLIDADO!$A:$A,BS_CONSOLIDADO!M:M,"")) | H18: =IF(COUNTBLANK(D18)=1,"",_xlfn.XLOOKUP(D18,BS_CONSOLIDADO!A:A,BS_CONSOLIDADO!N:N,"")) | I18: =IF(COUNTBLANK(D18)=1,"",_xlfn.XLOOKUP(D18,BS_CONSOLIDADO!A:A,BS_CONSOLIDADO!O:O,"")) | J18: =IF(COUNTBLANK(D18)=1,"",_xlfn.XLOOKUP(D18,BS_CONSOLIDADO!A:A,BS_CONSOLIDADO!P:P,"")) | L18: =IF(COUNTBLANK(D18)=1,"",_xlfn.XLOOKUP(D18,BS_SIMULADOR!A:A,BS_SIMULADOR!D:D,"")) | M18: =IF(COUNTBLANK(D18)=1,"",_xlfn.XLOOKUP(D18,BS_SIMULADOR!A:A,BS_SIMULADOR!Q:Q,"")) | N18: =IF(COUNTBLANK($D18)=1,"",_xlfn.XLOOKUP($D18,BS_SIMULADOR!$A:$A,BS_SIMULADOR!M:M,"")) | O18: =IF(COUNTBLANK(D18)=1,"",_xlfn.XLOOKUP(D18,BS_SIMULADOR!A:A,BS_SIMULADOR!N:N,"")) | P18: =IF(COUNTBLANK(D18)=1,"",_xlfn.XLOOKUP(D18,BS_SIMULADOR!A:A,BS_SIMULADOR!O:O,"")) | Q18: =IF(COUNTBLANK($D18)=1,"",_xlfn.XLOOKUP($D18,BS_SIMULADOR!$A:$A,BS_SIMULADOR!P:P,"")) | S18: =IFERROR(IF(COUNTBLANK(D18)=1,"",E18-L18)*(-1),"") | T18: =IFERROR(IF(COUNTBLANK($D18)=1,"",(_xlfn.XLOOKUP($D18,BS_CONSOLIDADO!$A:$A,BS_CONSOLIDADO!F:F,""))-(_xlfn.XLOOKUP($D18,BS_SIMULADOR!$A:$A,BS_SIMULADOR!F:F,"")))*(-1),"") | U18: =IFERROR(IF(COUNTBLANK(D18)=1,"",(_xlfn.XLOOKUP(D18,BS_CONSOLIDADO!A:A,BS_CONSOLIDADO!H:H,""))-(_xlfn.XLOOKUP(D18,BS_SIMULADOR!A:A,BS_SIMULADOR!H:H,"")))*(-1),"") | V18: =IFERROR(IF(COUNTBLANK(D18)=1,"",(_xlfn.XLOOKUP(D18,BS_CONSOLIDADO!A:A,BS_CONSOLIDADO!J:J,""))-(_xlfn.XLOOKUP(D18,BS_SIMULADOR!A:A,BS_SIMULADOR!J:J,"")))*(-1),"") | W18: =IFERROR(IF(COUNTBLANK($D18)=1,"",(_xlfn.XLOOKUP($D18,BS_CONSOLIDADO!$A:$A,BS_CONSOLIDADO!L:L,""))-(_xlfn.XLOOKUP($D18,BS_SIMULADOR!$A:$A,BS_SIMULADOR!L:L,"")))*(-1),"")
... A20: Parceiro 15 | E20: =IF(COUNTBLANK(D20)=1,"",_xlfn.XLOOKUP(D20,BS_CONSOLIDADO!A:A,BS_CONSOLIDADO!D:D,"")) | F20: =IF(COUNTBLANK(D20)=1,"",_xlfn.XLOOKUP(D20,BS_CONSOLIDADO!A:A,BS_CONSOLIDADO!Q:Q,"")) | G20: =IF(COUNTBLANK($D20)=1,"",_xlfn.XLOOKUP($D20,BS_CONSOLIDADO!$A:$A,BS_CONSOLIDADO!M:M,"")) | H20: =IF(COUNTBLANK(D20)=1,"",_xlfn.XLOOKUP(D20,BS_CONSOLIDADO!A:A,BS_CONSOLIDADO!N:N,"")) | I20: =IF(COUNTBLANK(D20)=1,"",_xlfn.XLOOKUP(D20,BS_CONSOLIDADO!A:A,BS_CONSOLIDADO!O:O,"")) | J20: =IF(COUNTBLANK(D20)=1,"",_xlfn.XLOOKUP(D20,BS_CONSOLIDADO!A:A,BS_CONSOLIDADO!P:P,"")) | L20: =IF(COUNTBLANK(D20)=1,"",_xlfn.XLOOKUP(D20,BS_SIMULADOR!A:A,BS_SIMULADOR!D:D,"")) | M20: =IF(COUNTBLANK(D20)=1,"",_xlfn.XLOOKUP(D20,BS_SIMULADOR!A:A,BS_SIMULADOR!Q:Q,"")) | N20: =IF(COUNTBLANK($D20)=1,"",_xlfn.XLOOKUP($D20,BS_SIMULADOR!$A:$A,BS_SIMULADOR!M:M,"")) | O20: =IF(COUNTBLANK(D20)=1,"",_xlfn.XLOOKUP(D20,BS_SIMULADOR!A:A,BS_SIMULADOR!N:N,"")) | P20: =IF(COUNTBLANK(D20)=1,"",_xlfn.XLOOKUP(D20,BS_SIMULADOR!A:A,BS_SIMULADOR!O:O,"")) | Q20: =IF(COUNTBLANK($D20)=1,"",_xlfn.XLOOKUP($D20,BS_SIMULADOR!$A:$A,BS_SIMULADOR!P:P,"")) | S20: =IFERROR(IF(COUNTBLANK(D20)=1,"",E20-L20)*(-1),"") | T20: =IFERROR(IF(COUNTBLANK($D20)=1,"",(_xlfn.XLOOKUP($D20,BS_CONSOLIDADO!$A:$A,BS_CONSOLIDADO!F:F,""))-(_xlfn.XLOOKUP($D20,BS_SIMULADOR!$A:$A,BS_SIMULADOR!F:F,"")))*(-1),"") | U20: =IFERROR(IF(COUNTBLANK(D20)=1,"",(_xlfn.XLOOKUP(D20,BS_CONSOLIDADO!A:A,BS_CONSOLIDADO!H:H,""))-(_xlfn.XLOOKUP(D20,BS_SIMULADOR!A:A,BS_SIMULADOR!H:H,"")))*(-1),"") | V20: =IFERROR(IF(COUNTBLANK(D20)=1,"",(_xlfn.XLOOKUP(D20,BS_CONSOLIDADO!A:A,BS_CONSOLIDADO!J:J,""))-(_xlfn.XLOOKUP(D20,BS_SIMULADOR!A:A,BS_SIMULADOR!J:J,"")))*(-1),"") | W20: =IFERROR(IF(COUNTBLANK($D20)=1,"",(_xlfn.XLOOKUP($D20,BS_CONSOLIDADO!$A:$A,BS_CONSOLIDADO!L:L,""))-(_xlfn.XLOOKUP($D20,BS_SIMULADOR!$A:$A,BS_SIMULADOR!L:L,"")))*(-1),"")
A21: Parceiro 16 | E21: =IF(COUNTBLANK(D21)=1,"",_xlfn.XLOOKUP(D21,BS_CONSOLIDADO!A:A,BS_CONSOLIDADO!D:D,"")) | F21: =IF(COUNTBLANK(D21)=1,"",_xlfn.XLOOKUP(D21,BS_CONSOLIDADO!A:A,BS_CONSOLIDADO!Q:Q,"")) | G21: =IF(COUNTBLANK($D21)=1,"",_xlfn.XLOOKUP($D21,BS_CONSOLIDADO!$A:$A,BS_CONSOLIDADO!M:M,"")) | H21: =IF(COUNTBLANK(D21)=1,"",_xlfn.XLOOKUP(D21,BS_CONSOLIDADO!A:A,BS_CONSOLIDADO!N:N,"")) | I21: =IF(COUNTBLANK(D21)=1,"",_xlfn.XLOOKUP(D21,BS_CONSOLIDADO!A:A,BS_CONSOLIDADO!O:O,"")) | J21: =IF(COUNTBLANK(D21)=1,"",_xlfn.XLOOKUP(D21,BS_CONSOLIDADO!A:A,BS_CONSOLIDADO!P:P,"")) | L21: =IF(COUNTBLANK(D21)=1,"",_xlfn.XLOOKUP(D21,BS_SIMULADOR!A:A,BS_SIMULADOR!D:D,"")) | M21: =IF(COUNTBLANK(D21)=1,"",_xlfn.XLOOKUP(D21,BS_SIMULADOR!A:A,BS_SIMULADOR!Q:Q,"")) | N21: =IF(COUNTBLANK($D21)=1,"",_xlfn.XLOOKUP($D21,BS_SIMULADOR!$A:$A,BS_SIMULADOR!M:M,"")) | O21: =IF(COUNTBLANK(D21)=1,"",_xlfn.XLOOKUP(D21,BS_SIMULADOR!A:A,BS_SIMULADOR!N:N,"")) | P21: =IF(COUNTBLANK(D21)=1,"",_xlfn.XLOOKUP(D21,BS_SIMULADOR!A:A,BS_SIMULADOR!O:O,"")) | Q21: =IF(COUNTBLANK($D21)=1,"",_xlfn.XLOOKUP($D21,BS_SIMULADOR!$A:$A,BS_SIMULADOR!P:P,"")) | S21: =IFERROR(IF(COUNTBLANK(D21)=1,"",E21-L21)*(-1),"") | T21: =IFERROR(IF(COUNTBLANK($D21)=1,"",(_xlfn.XLOOKUP($D21,BS_CONSOLIDADO!$A:$A,BS_CONSOLIDADO!F:F,""))-(_xlfn.XLOOKUP($D21,BS_SIMULADOR!$A:$A,BS_SIMULADOR!F:F,"")))*(-1),"") | V21: =IFERROR(IF(COUNTBLANK(D21)=1,"",(_xlfn.XLOOKUP(D21,BS_CONSOLIDADO!A:A,BS_CONSOLIDADO!J:J,""))-(_xlfn.XLOOKUP(D21,BS_SIMULADOR!A:A,BS_SIMULADOR!J:J,"")))*(-1),"") | W21: =IFERROR(IF(COUNTBLANK($D21)=1,"",(_xlfn.XLOOKUP($D21,BS_CONSOLIDADO!$A:$A,BS_CONSOLIDADO!L:L,""))-(_xlfn.XLOOKUP($D21,BS_SIMULADOR!$A:$A,BS_SIMULADOR!L:L,"")))*(-1),"")
A22: Parceiro 17 | B22: e1 | E22: =IF(COUNTBLANK(D22)=1,"",_xlfn.XLOOKUP(D22,BS_CONSOLIDADO!A:A,BS_CONSOLIDADO!D:D,"")) | F22: =IF(COUNTBLANK(D22)=1,"",_xlfn.XLOOKUP(D22,BS_CONSOLIDADO!A:A,BS_CONSOLIDADO!Q:Q,"")) | G22: =IF(COUNTBLANK($D22)=1,"",_xlfn.XLOOKUP($D22,BS_CONSOLIDADO!$A:$A,BS_CONSOLIDADO!M:M,"")) | H22: =IF(COUNTBLANK(D22)=1,"",_xlfn.XLOOKUP(D22,BS_CONSOLIDADO!A:A,BS_CONSOLIDADO!N:N,"")) | I22: =IF(COUNTBLANK(D22)=1,"",_xlfn.XLOOKUP(D22,BS_CONSOLIDADO!A:A,BS_CONSOLIDADO!O:O,"")) | J22: =IF(COUNTBLANK(D22)=1,"",_xlfn.XLOOKUP(D22,BS_CONSOLIDADO!A:A,BS_CONSOLIDADO!P:P,"")) | L22: =IF(COUNTBLANK(D22)=1,"",_xlfn.XLOOKUP(D22,BS_SIMULADOR!A:A,BS_SIMULADOR!D:D,"")) | M22: =IF(COUNTBLANK(D22)=1,"",_xlfn.XLOOKUP(D22,BS_SIMULADOR!A:A,BS_SIMULADOR!Q:Q,"")) | N22: =IF(COUNTBLANK($D22)=1,"",_xlfn.XLOOKUP($D22,BS_SIMULADOR!$A:$A,BS_SIMULADOR!M:M,"")) | O22: =IF(COUNTBLANK(D22)=1,"",_xlfn.XLOOKUP(D22,BS_SIMULADOR!A:A,BS_SIMULADOR!N:N,"")) | P22: =IF(COUNTBLANK(D22)=1,"",_xlfn.XLOOKUP(D22,BS_SIMULADOR!A:A,BS_SIMULADOR!O:O,"")) | Q22: =IF(COUNTBLANK($D22)=1,"",_xlfn.XLOOKUP($D22,BS_SIMULADOR!$A:$A,BS_SIMULADOR!P:P,"")) | S22: =IFERROR(IF(COUNTBLANK(D22)=1,"",E22-L22)*(-1),"") | T22: =IFERROR(IF(COUNTBLANK($D22)=1,"",(_xlfn.XLOOKUP($D22,BS_CONSOLIDADO!$A:$A,BS_CONSOLIDADO!F:F,""))-(_xlfn.XLOOKUP($D22,BS_SIMULADOR!$A:$A,BS_SIMULADOR!F:F,"")))*(-1),"") | U22: =IFERROR(IF(COUNTBLANK(D22)=1,"",(_xlfn.XLOOKUP(D22,BS_CONSOLIDADO!A:A,BS_CONSOLIDADO!H:H,""))-(_xlfn.XLOOKUP(D22,BS_SIMULADOR!A:A,BS_SIMULADOR!H:H,"")))*(-1),"") | V22: =IFERROR(IF(COUNTBLANK(D22)=1,"",(_xlfn.XLOOKUP(D22,BS_CONSOLIDADO!A:A,BS_CONSOLIDADO!J:J,""))-(_xlfn.XLOOKUP(D22,BS_SIMULADOR!A:A,BS_SIMULADOR!J:J,"")))*(-1),"") | W22: =IFERROR(IF(COUNTBLANK($D22)=1,"",(_xlfn.XLOOKUP($D22,BS_CONSOLIDADO!$A:$A,BS_CONSOLIDADO!L:L,""))-(_xlfn.XLOOKUP($D22,BS_SIMULADOR!$A:$A,BS_SIMULADOR!L:L,"")))*(-1),"")
A23: Parceiro 18 | E23: =IF(COUNTBLANK(D23)=1,"",_xlfn.XLOOKUP(D23,BS_CONSOLIDADO!A:A,BS_CONSOLIDADO!D:D,"")) | F23: =IF(COUNTBLANK(D23)=1,"",_xlfn.XLOOKUP(D23,BS_CONSOLIDADO!A:A,BS_CONSOLIDADO!Q:Q,"")) | G23: =IF(COUNTBLANK($D23)=1,"",_xlfn.XLOOKUP($D23,BS_CONSOLIDADO!$A:$A,BS_CONSOLIDADO!M:M,"")) | H23: =IF(COUNTBLANK(D23)=1,"",_xlfn.XLOOKUP(D23,BS_CONSOLIDADO!A:A,BS_CONSOLIDADO!N:N,"")) | I23: =IF(COUNTBLANK(D23)=1,"",_xlfn.XLOOKUP(D23,BS_CONSOLIDADO!A:A,BS_CONSOLIDADO!O:O,"")) | J23: =IF(COUNTBLANK(D23)=1,"",_xlfn.XLOOKUP(D23,BS_CONSOLIDADO!A:A,BS_CONSOLIDADO!P:P,"")) | L23: =IF(COUNTBLANK(D23)=1,"",_xlfn.XLOOKUP(D23,BS_SIMULADOR!A:A,BS_SIMULADOR!D:D,"")) | M23: =IF(COUNTBLANK(D23)=1,"",_xlfn.XLOOKUP(D23,BS_SIMULADOR!A:A,BS_SIMULADOR!Q:Q,"")) | N23: =IF(COUNTBLANK($D23)=1,"",_xlfn.XLOOKUP($D23,BS_SIMULADOR!$A:$A,BS_SIMULADOR!M:M,"")) | O23: =IF(COUNTBLANK(D23)=1,"",_xlfn.XLOOKUP(D23,BS_SIMULADOR!A:A,BS_SIMULADOR!N:N,"")) | P23: =IF(COUNTBLANK(D23)=1,"",_xlfn.XLOOKUP(D23,BS_SIMULADOR!A:A,BS_SIMULADOR!O:O,"")) | Q23: =IF(COUNTBLANK($D23)=1,"",_xlfn.XLOOKUP($D23,BS_SIMULADOR!$A:$A,BS_SIMULADOR!P:P,"")) | S23: =IFERROR(IF(COUNTBLANK(D23)=1,"",E23-L23)*(-1),"") | T23: =IFERROR(IF(COUNTBLANK($D23)=1,"",(_xlfn.XLOOKUP($D23,BS_CONSOLIDADO!$A:$A,BS_CONSOLIDADO!F:F,""))-(_xlfn.XLOOKUP($D23,BS_SIMULADOR!$A:$A,BS_SIMULADOR!F:F,"")))*(-1),"") | U23: =IFERROR(IF(COUNTBLANK(D23)=1,"",(_xlfn.XLOOKUP(D23,BS_CONSOLIDADO!A:A,BS_CONSOLIDADO!H:H,""))-(_xlfn.XLOOKUP(D23,BS_SIMULADOR!A:A,BS_SIMULADOR!H:H,"")))*(-1),"") | V23: =IFERROR(IF(COUNTBLANK(D23)=1,"",(_xlfn.XLOOKUP(D23,BS_CONSOLIDADO!A:A,BS_CONSOLIDADO!J:J,""))-(_xlfn.XLOOKUP(D23,BS_SIMULADOR!A:A,BS_SIMULADOR!J:J,"")))*(-1),"") | W23: =IFERROR(IF(COUNTBLANK($D23)=1,"",(_xlfn.XLOOKUP($D23,BS_CONSOLIDADO!$A:$A,BS_CONSOLIDADO!L:L,""))-(_xlfn.XLOOKUP($D23,BS_SIMULADOR!$A:$A,BS_SIMULADOR!L:L,"")))*(-1),"")
A24: Parceiro 19 | E24: =IF(COUNTBLANK(D24)=1,"",_xlfn.XLOOKUP(D24,BS_CONSOLIDADO!A:A,BS_CONSOLIDADO!D:D,"")) | F24: =IF(COUNTBLANK(D24)=1,"",_xlfn.XLOOKUP(D24,BS_CONSOLIDADO!A:A,BS_CONSOLIDADO!Q:Q,"")) | G24: =IF(COUNTBLANK($D24)=1,"",_xlfn.XLOOKUP($D24,BS_CONSOLIDADO!$A:$A,BS_CONSOLIDADO!M:M,"")) | H24: =IF(COUNTBLANK(D24)=1,"",_xlfn.XLOOKUP(D24,BS_CONSOLIDADO!A:A,BS_CONSOLIDADO!N:N,"")) | I24: =IF(COUNTBLANK(D24)=1,"",_xlfn.XLOOKUP(D24,BS_CONSOLIDADO!A:A,BS_CONSOLIDADO!O:O,"")) | J24: =IF(COUNTBLANK(D24)=1,"",_xlfn.XLOOKUP(D24,BS_CONSOLIDADO!A:A,BS_CONSOLIDADO!P:P,"")) | L24: =IF(COUNTBLANK(D24)=1,"",_xlfn.XLOOKUP(D24,BS_SIMULADOR!A:A,BS_SIMULADOR!D:D,"")) | M24: =IF(COUNTBLANK(D24)=1,"",_xlfn.XLOOKUP(D24,BS_SIMULADOR!A:A,BS_SIMULADOR!Q:Q,"")) | N24: =IF(COUNTBLANK($D24)=1,"",_xlfn.XLOOKUP($D24,BS_SIMULADOR!$A:$A,BS_SIMULADOR!M:M,"")) | O24: =IF(COUNTBLANK(D24)=1,"",_xlfn.XLOOKUP(D24,BS_SIMULADOR!A:A,BS_SIMULADOR!N:N,"")) | P24: =IF(COUNTBLANK(D24)=1,"",_xlfn.XLOOKUP(D24,BS_SIMULADOR!A:A,BS_SIMULADOR!O:O,"")) | Q24: =IF(COUNTBLANK($D24)=1,"",_xlfn.XLOOKUP($D24,BS_SIMULADOR!$A:$A,BS_SIMULADOR!P:P,"")) | S24: =IFERROR(IF(COUNTBLANK(D24)=1,"",E24-L24)*(-1),"") | T24: =IFERROR(IF(COUNTBLANK($D24)=1,"",(_xlfn.XLOOKUP($D24,BS_CONSOLIDADO!$A:$A,BS_CONSOLIDADO!F:F,""))-(_xlfn.XLOOKUP($D24,BS_SIMULADOR!$A:$A,BS_SIMULADOR!F:F,"")))*(-1),"") | U24: =IFERROR(IF(COUNTBLANK(D24)=1,"",(_xlfn.XLOOKUP(D24,BS_CONSOLIDADO!A:A,BS_CONSOLIDADO!H:H,""))-(_xlfn.XLOOKUP(D24,BS_SIMULADOR!A:A,BS_SIMULADOR!H:H,"")))*(-1),"") | V24: =IFERROR(IF(COUNTBLANK(D24)=1,"",(_xlfn.XLOOKUP(D24,BS_CONSOLIDADO!A:A,BS_CONSOLIDADO!J:J,""))-(_xlfn.XLOOKUP(D24,BS_SIMULADOR!A:A,BS_SIMULADOR!J:J,"")))*(-1),"") | W24: =IFERROR(IF(COUNTBLANK($D24)=1,"",(_xlfn.XLOOKUP($D24,BS_CONSOLIDADO!$A:$A,BS_CONSOLIDADO!L:L,""))-(_xlfn.XLOOKUP($D24,BS_SIMULADOR!$A:$A,BS_SIMULADOR!L:L,"")))*(-1),"")
A25: Parceiro 20 | E25: =IF(COUNTBLANK(D25)=1,"",_xlfn.XLOOKUP(D25,BS_CONSOLIDADO!A:A,BS_CONSOLIDADO!D:D,"")) | F25: =IF(COUNTBLANK(D25)=1,"",_xlfn.XLOOKUP(D25,BS_CONSOLIDADO!A:A,BS_CONSOLIDADO!Q:Q,"")) | G25: =IF(COUNTBLANK($D25)=1,"",_xlfn.XLOOKUP($D25,BS_CONSOLIDADO!$A:$A,BS_CONSOLIDADO!M:M,"")) | H25: =IF(COUNTBLANK(D25)=1,"",_xlfn.XLOOKUP(D25,BS_CONSOLIDADO!A:A,BS_CONSOLIDADO!N:N,"")) | I25: =IF(COUNTBLANK(D25)=1,"",_xlfn.XLOOKUP(D25,BS_CONSOLIDADO!A:A,BS_CONSOLIDADO!O:O,"")) | J25: =IF(COUNTBLANK(D25)=1,"",_xlfn.XLOOKUP(D25,BS_CONSOLIDADO!A:A,BS_CONSOLIDADO!P:P,"")) | L25: =IF(COUNTBLANK(D25)=1,"",_xlfn.XLOOKUP(D25,BS_SIMULADOR!A:A,BS_SIMULADOR!D:D,"")) | M25: =IF(COUNTBLANK(D25)=1,"",_xlfn.XLOOKUP(D25,BS_SIMULADOR!A:A,BS_SIMULADOR!Q:Q,"")) | N25: =IF(COUNTBLANK($D25)=1,"",_xlfn.XLOOKUP($D25,BS_SIMULADOR!$A:$A,BS_SIMULADOR!M:M,"")) | O25: =IF(COUNTBLANK(D25)=1,"",_xlfn.XLOOKUP(D25,BS_SIMULADOR!A:A,BS_SIMULADOR!N:N,"")) | P25: =IF(COUNTBLANK(D25)=1,"",_xlfn.XLOOKUP(D25,BS_SIMULADOR!A:A,BS_SIMULADOR!O:O,"")) | Q25: =IF(COUNTBLANK($D25)=1,"",_xlfn.XLOOKUP($D25,BS_SIMULADOR!$A:$A,BS_SIMULADOR!P:P,"")) | S25: =IFERROR(IF(COUNTBLANK(D25)=1,"",E25-L25)*(-1),"") | T25: =IFERROR(IF(COUNTBLANK($D25)=1,"",(_xlfn.XLOOKUP($D25,BS_CONSOLIDADO!$A:$A,BS_CONSOLIDADO!F:F,""))-(_xlfn.XLOOKUP($D25,BS_SIMULADOR!$A:$A,BS_SIMULADOR!F:F,"")))*(-1),"") | U25: =IFERROR(IF(COUNTBLANK(D25)=1,"",(_xlfn.XLOOKUP(D25,BS_CONSOLIDADO!A:A,BS_CONSOLIDADO!H:H,""))-(_xlfn.XLOOKUP(D25,BS_SIMULADOR!A:A,BS_SIMULADOR!H:H,"")))*(-1),"") | V25: =IFERROR(IF(COUNTBLANK(D25)=1,"",(_xlfn.XLOOKUP(D25,BS_CONSOLIDADO!A:A,BS_CONSOLIDADO!J:J,""))-(_xlfn.XLOOKUP(D25,BS_SIMULADOR!A:A,BS_SIMULADOR!J:J,"")))*(-1),"") | W25: =IFERROR(IF(COUNTBLANK($D25)=1,"",(_xlfn.XLOOKUP($D25,BS_CONSOLIDADO!$A:$A,BS_CONSOLIDADO!L:L,""))-(_xlfn.XLOOKUP($D25,BS_SIMULADOR!$A:$A,BS_SIMULADOR!L:L,"")))*(-1),"")
E26: =IF(COUNTBLANK(D26)=1,"",_xlfn.XLOOKUP(D26,BS_CONSOLIDADO!A:A,BS_CONSOLIDADO!D:D,"")) | F26: =IF(COUNTBLANK(D26)=1,"",_xlfn.XLOOKUP(D26,BS_CONSOLIDADO!A:A,BS_CONSOLIDADO!Q:Q,"")) | G26: =IF(COUNTBLANK($D26)=1,"",_xlfn.XLOOKUP($D26,BS_CONSOLIDADO!$A:$A,BS_CONSOLIDADO!M:M,"")) | H26: =IF(COUNTBLANK(D26)=1,"",_xlfn.XLOOKUP(D26,BS_CONSOLIDADO!A:A,BS_CONSOLIDADO!N:N,"")) | I26: =IF(COUNTBLANK(D26)=1,"",_xlfn.XLOOKUP(D26,BS_CONSOLIDADO!A:A,BS_CONSOLIDADO!O:O,"")) | J26: =IF(COUNTBLANK(D26)=1,"",_xlfn.XLOOKUP(D26,BS_CONSOLIDADO!A:A,BS_CONSOLIDADO!P:P,"")) | L26: =IF(COUNTBLANK(D26)=1,"",_xlfn.XLOOKUP(D26,BS_SIMULADOR!A:A,BS_SIMULADOR!D:D,"")) | M26: =IF(COUNTBLANK(D26)=1,"",_xlfn.XLOOKUP(D26,BS_SIMULADOR!A:A,BS_SIMULADOR!Q:Q,"")) | N26: =IF(COUNTBLANK($D26)=1,"",_xlfn.XLOOKUP($D26,BS_SIMULADOR!$A:$A,BS_SIMULADOR!M:M,"")) | O26: =IF(COUNTBLANK(D26)=1,"",_xlfn.XLOOKUP(D26,BS_SIMULADOR!A:A,BS_SIMULADOR!N:N,"")) | P26: =IF(COUNTBLANK(D26)=1,"",_xlfn.XLOOKUP(D26,BS_SIMULADOR!A:A,BS_SIMULADOR!O:O,"")) | Q26: =IF(COUNTBLANK($D26)=1,"",_xlfn.XLOOKUP($D26,BS_SIMULADOR!$A:$A,BS_SIMULADOR!P:P,"")) | S26: =IFERROR(IF(COUNTBLANK(D26)=1,"",E26-L26)*(-1),"") | T26: =IFERROR(IF(COUNTBLANK($D26)=1,"",(_xlfn.XLOOKUP($D26,BS_CONSOLIDADO!$A:$A,BS_CONSOLIDADO!F:F,""))-(_xlfn.XLOOKUP($D26,BS_SIMULADOR!$A:$A,BS_SIMULADOR!F:F,"")))*(-1),"") | U26: =IFERROR(IF(COUNTBLANK(D26)=1,"",(_xlfn.XLOOKUP(D26,BS_CONSOLIDADO!A:A,BS_CONSOLIDADO!H:H,""))-(_xlfn.XLOOKUP(D26,BS_SIMULADOR!A:A,BS_SIMULADOR!H:H,"")))*(-1),"") | V26: =IFERROR(IF(COUNTBLANK(D26)=1,"",(_xlfn.XLOOKUP(D26,BS_CONSOLIDADO!A:A,BS_CONSOLIDADO!J:J,""))-(_xlfn.XLOOKUP(D26,BS_SIMULADOR!A:A,BS_SIMULADOR!J:J,"")))*(-1),"") | W26: =IFERROR(IF(COUNTBLANK($D26)=1,"",(_xlfn.XLOOKUP($D26,BS_CONSOLIDADO!$A:$A,BS_CONSOLIDADO!L:L,""))-(_xlfn.XLOOKUP($D26,BS_SIMULADOR!$A:$A,BS_SIMULADOR!L:L,"")))*(-1),"")
E27: =IF(COUNTBLANK(D27)=1,"",_xlfn.XLOOKUP(D27,BS_CONSOLIDADO!A:A,BS_CONSOLIDADO!D:D,"")) | F27: =IF(COUNTBLANK(D27)=1,"",_xlfn.XLOOKUP(D27,BS_CONSOLIDADO!A:A,BS_CONSOLIDADO!Q:Q,"")) | G27: =IF(COUNTBLANK($D27)=1,"",_xlfn.XLOOKUP($D27,BS_CONSOLIDADO!$A:$A,BS_CONSOLIDADO!M:M,"")) | H27: =IF(COUNTBLANK(D27)=1,"",_xlfn.XLOOKUP(D27,BS_CONSOLIDADO!A:A,BS_CONSOLIDADO!N:N,"")) | I27: =IF(COUNTBLANK(D27)=1,"",_xlfn.XLOOKUP(D27,BS_CONSOLIDADO!A:A,BS_CONSOLIDADO!O:O,"")) | J27: =IF(COUNTBLANK(D27)=1,"",_xlfn.XLOOKUP(D27,BS_CONSOLIDADO!A:A,BS_CONSOLIDADO!P:P,"")) | L27: =IF(COUNTBLANK(D27)=1,"",_xlfn.XLOOKUP(D27,BS_SIMULADOR!A:A,BS_SIMULADOR!D:D,"")) | M27: =IF(COUNTBLANK(D27)=1,"",_xlfn.XLOOKUP(D27,BS_SIMULADOR!A:A,BS_SIMULADOR!Q:Q,"")) | N27: =IF(COUNTBLANK($D27)=1,"",_xlfn.XLOOKUP($D27,BS_SIMULADOR!$A:$A,BS_SIMULADOR!M:M,"")) | O27: =IF(COUNTBLANK(D27)=1,"",_xlfn.XLOOKUP(D27,BS_SIMULADOR!A:A,BS_SIMULADOR!N:N,"")) | P27: =IF(COUNTBLANK(D27)=1,"",_xlfn.XLOOKUP(D27,BS_SIMULADOR!A:A,BS_SIMULADOR!O:O,"")) | Q27: =IF(COUNTBLANK($D27)=1,"",_xlfn.XLOOKUP($D27,BS_SIMULADOR!$A:$A,BS_SIMULADOR!P:P,"")) | S27: =IFERROR(IF(COUNTBLANK(D27)=1,"",E27-L27)*(-1),"") | T27: =IFERROR(IF(COUNTBLANK($D27)=1,"",(_xlfn.XLOOKUP($D27,BS_CONSOLIDADO!$A:$A,BS_CONSOLIDADO!F:F,""))-(_xlfn.XLOOKUP($D27,BS_SIMULADOR!$A:$A,BS_SIMULADOR!F:F,"")))*(-1),"") | U27: =IFERROR(IF(COUNTBLANK(D27)=1,"",(_xlfn.XLOOKUP(D27,BS_CONSOLIDADO!A:A,BS_CONSOLIDADO!H:H,""))-(_xlfn.XLOOKUP(D27,BS_SIMULADOR!A:A,BS_SIMULADOR!H:H,"")))*(-1),"") | V27: =IFERROR(IF(COUNTBLANK(D27)=1,"",(_xlfn.XLOOKUP(D27,BS_CONSOLIDADO!A:A,BS_CONSOLIDADO!J:J,""))-(_xlfn.XLOOKUP(D27,BS_SIMULADOR!A:A,BS_SIMULADOR!J:J,"")))*(-1),"") | W27: =IFERROR(IF(COUNTBLANK($D27)=1,"",(_xlfn.XLOOKUP($D27,BS_CONSOLIDADO!$A:$A,BS_CONSOLIDADO!L:L,""))-(_xlfn.XLOOKUP($D27,BS_SIMULADOR!$A:$A,BS_SIMULADOR!L:L,"")))*(-1),"")
E28: =IF(COUNTBLANK(D28)=1,"",_xlfn.XLOOKUP(D28,BS_CONSOLIDADO!A:A,BS_CONSOLIDADO!D:D,"")) | F28: =IF(COUNTBLANK(D28)=1,"",_xlfn.XLOOKUP(D28,BS_CONSOLIDADO!A:A,BS_CONSOLIDADO!Q:Q,"")) | G28: =IF(COUNTBLANK($D28)=1,"",_xlfn.XLOOKUP($D28,BS_CONSOLIDADO!$A:$A,BS_CONSOLIDADO!M:M,"")) | H28: =IF(COUNTBLANK(D28)=1,"",_xlfn.XLOOKUP(D28,BS_CONSOLIDADO!A:A,BS_CONSOLIDADO!N:N,"")) | I28: =IF(COUNTBLANK(D28)=1,"",_xlfn.XLOOKUP(D28,BS_CONSOLIDADO!A:A,BS_CONSOLIDADO!O:O,"")) | J28: =IF(COUNTBLANK(D28)=1,"",_xlfn.XLOOKUP(D28,BS_CONSOLIDADO!A:A,BS_CONSOLIDADO!P:P,"")) | L28: =IF(COUNTBLANK(D28)=1,"",_xlfn.XLOOKUP(D28,BS_SIMULADOR!A:A,BS_SIMULADOR!D:D,"")) | M28: =IF(COUNTBLANK(D28)=1,"",_xlfn.XLOOKUP(D28,BS_SIMULADOR!A:A,BS_SIMULADOR!Q:Q,"")) | N28: =IF(COUNTBLANK($D28)=1,"",_xlfn.XLOOKUP($D28,BS_SIMULADOR!$A:$A,BS_SIMULADOR!M:M,"")) | O28: =IF(COUNTBLANK(D28)=1,"",_xlfn.XLOOKUP(D28,BS_SIMULADOR!A:A,BS_SIMULADOR!N:N,"")) | P28: =IF(COUNTBLANK(D28)=1,"",_xlfn.XLOOKUP(D28,BS_SIMULADOR!A:A,BS_SIMULADOR!O:O,"")) | Q28: =IF(COUNTBLANK($D28)=1,"",_xlfn.XLOOKUP($D28,BS_SIMULADOR!$A:$A,BS_SIMULADOR!P:P,"")) | S28: =IFERROR(IF(COUNTBLANK(D28)=1,"",E28-L28)*(-1),"") | T28: =IFERROR(IF(COUNTBLANK($D28)=1,"",(_xlfn.XLOOKUP($D28,BS_CONSOLIDADO!$A:$A,BS_CONSOLIDADO!F:F,""))-(_xlfn.XLOOKUP($D28,BS_SIMULADOR!$A:$A,BS_SIMULADOR!F:F,"")))*(-1),"") | U28: =IFERROR(IF(COUNTBLANK(D28)=1,"",(_xlfn.XLOOKUP(D28,BS_CONSOLIDADO!A:A,BS_CONSOLIDADO!H:H,""))-(_xlfn.XLOOKUP(D28,BS_SIMULADOR!A:A,BS_SIMULADOR!H:H,"")))*(-1),"") | V28: =IFERROR(IF(COUNTBLANK(D28)=1,"",(_xlfn.XLOOKUP(D28,BS_CONSOLIDADO!A:A,BS_CONSOLIDADO!J:J,""))-(_xlfn.XLOOKUP(D28,BS_SIMULADOR!A:A,BS_SIMULADOR!J:J,"")))*(-1),"") | W28: =IFERROR(IF(COUNTBLANK($D28)=1,"",(_xlfn.XLOOKUP($D28,BS_CONSOLIDADO!$A:$A,BS_CONSOLIDADO!L:L,""))-(_xlfn.XLOOKUP($D28,BS_SIMULADOR!$A:$A,BS_SIMULADOR!L:L,"")))*(-1),"")
E29: =IF(COUNTBLANK(D29)=1,"",_xlfn.XLOOKUP(D29,BS_CONSOLIDADO!A:A,BS_CONSOLIDADO!D:D,"")) | F29: =IF(COUNTBLANK(D29)=1,"",_xlfn.XLOOKUP(D29,BS_CONSOLIDADO!A:A,BS_CONSOLIDADO!Q:Q,"")) | G29: =IF(COUNTBLANK($D29)=1,"",_xlfn.XLOOKUP($D29,BS_CONSOLIDADO!$A:$A,BS_CONSOLIDADO!M:M,"")) | H29: =IF(COUNTBLANK(D29)=1,"",_xlfn.XLOOKUP(D29,BS_CONSOLIDADO!A:A,BS_CONSOLIDADO!N:N,"")) | I29: =IF(COUNTBLANK(D29)=1,"",_xlfn.XLOOKUP(D29,BS_CONSOLIDADO!A:A,BS_CONSOLIDADO!O:O,"")) | J29: =IF(COUNTBLANK(D29)=1,"",_xlfn.XLOOKUP(D29,BS_CONSOLIDADO!A:A,BS_CONSOLIDADO!P:P,"")) | L29: =IF(COUNTBLANK(D29)=1,"",_xlfn.XLOOKUP(D29,BS_SIMULADOR!A:A,BS_SIMULADOR!D:D,"")) | M29: =IF(COUNTBLANK(D29)=1,"",_xlfn.XLOOKUP(D29,BS_SIMULADOR!A:A,BS_SIMULADOR!Q:Q,"")) | N29: =IF(COUNTBLANK($D29)=1,"",_xlfn.XLOOKUP($D29,BS_SIMULADOR!$A:$A,BS_SIMULADOR!M:M,"")) | O29: =IF(COUNTBLANK(D29)=1,"",_xlfn.XLOOKUP(D29,BS_SIMULADOR!A:A,BS_SIMULADOR!N:N,"")) | P29: =IF(COUNTBLANK(D29)=1,"",_xlfn.XLOOKUP(D29,BS_SIMULADOR!A:A,BS_SIMULADOR!O:O,"")) | Q29: =IF(COUNTBLANK($D29)=1,"",_xlfn.XLOOKUP($D29,BS_SIMULADOR!$A:$A,BS_SIMULADOR!P:P,"")) | S29: =IFERROR(IF(COUNTBLANK(D29)=1,"",E29-L29)*(-1),"") | T29: =IFERROR(IF(COUNTBLANK($D29)=1,"",(_xlfn.XLOOKUP($D29,BS_CONSOLIDADO!$A:$A,BS_CONSOLIDADO!F:F,""))-(_xlfn.XLOOKUP($D29,BS_SIMULADOR!$A:$A,BS_SIMULADOR!F:F,"")))*(-1),"") | U29: =IFERROR(IF(COUNTBLANK(D29)=1,"",(_xlfn.XLOOKUP(D29,BS_CONSOLIDADO!A:A,BS_CONSOLIDADO!H:H,""))-(_xlfn.XLOOKUP(D29,BS_SIMULADOR!A:A,BS_SIMULADOR!H:H,"")))*(-1),"") | V29: =IFERROR(IF(COUNTBLANK(D29)=1,"",(_xlfn.XLOOKUP(D29,BS_CONSOLIDADO!A:A,BS_CONSOLIDADO!J:J,""))-(_xlfn.XLOOKUP(D29,BS_SIMULADOR!A:A,BS_SIMULADOR!J:J,"")))*(-1),"") | W29: =IFERROR(IF(COUNTBLANK($D29)=1,"",(_xlfn.XLOOKUP($D29,BS_CONSOLIDADO!$A:$A,BS_CONSOLIDADO!L:L,""))-(_xlfn.XLOOKUP($D29,BS_SIMULADOR!$A:$A,BS_SIMULADOR!L:L,"")))*(-1),"")
E30: =IF(COUNTBLANK(D30)=1,"",_xlfn.XLOOKUP(D30,BS_CONSOLIDADO!A:A,BS_CONSOLIDADO!D:D,"")) | F30: =IF(COUNTBLANK(D30)=1,"",_xlfn.XLOOKUP(D30,BS_CONSOLIDADO!A:A,BS_CONSOLIDADO!Q:Q,"")) | G30: =IF(COUNTBLANK($D30)=1,"",_xlfn.XLOOKUP($D30,BS_CONSOLIDADO!$A:$A,BS_CONSOLIDADO!M:M,"")) | H30: =IF(COUNTBLANK(D30)=1,"",_xlfn.XLOOKUP(D30,BS_CONSOLIDADO!A:A,BS_CONSOLIDADO!N:N,"")) | I30: =IF(COUNTBLANK(D30)=1,"",_xlfn.XLOOKUP(D30,BS_CONSOLIDADO!A:A,BS_CONSOLIDADO!O:O,"")) | J30: =IF(COUNTBLANK(D30)=1,"",_xlfn.XLOOKUP(D30,BS_CONSOLIDADO!A:A,BS_CONSOLIDADO!P:P,"")) | L30: =IF(COUNTBLANK(D30)=1,"",_xlfn.XLOOKUP(D30,BS_SIMULADOR!A:A,BS_SIMULADOR!D:D,"")) | M30: =IF(COUNTBLANK(D30)=1,"",_xlfn.XLOOKUP(D30,BS_SIMULADOR!A:A,BS_SIMULADOR!Q:Q,"")) | N30: =IF(COUNTBLANK($D30)=1,"",_xlfn.XLOOKUP($D30,BS_SIMULADOR!$A:$A,BS_SIMULADOR!M:M,"")) | O30: =IF(COUNTBLANK(D30)=1,"",_xlfn.XLOOKUP(D30,BS_SIMULADOR!A:A,BS_SIMULADOR!N:N,"")) | P30: =IF(COUNTBLANK(D30)=1,"",_xlfn.XLOOKUP(D30,BS_SIMULADOR!A:A,BS_SIMULADOR!O:O,"")) | Q30: =IF(COUNTBLANK($D30)=1,"",_xlfn.XLOOKUP($D30,BS_SIMULADOR!$A:$A,BS_SIMULADOR!P:P,"")) | S30: =IFERROR(IF(COUNTBLANK(D30)=1,"",E30-L30)*(-1),"") | T30: =IFERROR(IF(COUNTBLANK($D30)=1,"",(_xlfn.XLOOKUP($D30,BS_CONSOLIDADO!$A:$A,BS_CONSOLIDADO!F:F,""))-(_xlfn.XLOOKUP($D30,BS_SIMULADOR!$A:$A,BS_SIMULADOR!F:F,"")))*(-1),"") | U30: =IFERROR(IF(COUNTBLANK(D30)=1,"",(_xlfn.XLOOKUP(D30,BS_CONSOLIDADO!A:A,BS_CONSOLIDADO!H:H,""))-(_xlfn.XLOOKUP(D30,BS_SIMULADOR!A:A,BS_SIMULADOR!H:H,"")))*(-1),"") | V30: =IFERROR(IF(COUNTBLANK(D30)=1,"",(_xlfn.XLOOKUP(D30,BS_CONSOLIDADO!A:A,BS_CONSOLIDADO!J:J,""))-(_xlfn.XLOOKUP(D30,BS_SIMULADOR!A:A,BS_SIMULADOR!J:J,"")))*(-1),"") | W30: =IFERROR(IF(COUNTBLANK($D30)=1,"",(_xlfn.XLOOKUP($D30,BS_CONSOLIDADO!$A:$A,BS_CONSOLIDADO!L:L,""))-(_xlfn.XLOOKUP($D30,BS_SIMULADOR!$A:$A,BS_SIMULADOR!L:L,"")))*(-1),"")
E31: =IF(COUNTBLANK(D31)=1,"",_xlfn.XLOOKUP(D31,BS_CONSOLIDADO!A:A,BS_CONSOLIDADO!D:D,"")) | F31: =IF(COUNTBLANK(D31)=1,"",_xlfn.XLOOKUP(D31,BS_CONSOLIDADO!A:A,BS_CONSOLIDADO!Q:Q,"")) | G31: =IF(COUNTBLANK($D31)=1,"",_xlfn.XLOOKUP($D31,BS_CONSOLIDADO!$A:$A,BS_CONSOLIDADO!M:M,"")) | H31: =IF(COUNTBLANK(D31)=1,"",_xlfn.XLOOKUP(D31,BS_CONSOLIDADO!A:A,BS_CONSOLIDADO!N:N,"")) | I31: =IF(COUNTBLANK(D31)=1,"",_xlfn.XLOOKUP(D31,BS_CONSOLIDADO!A:A,BS_CONSOLIDADO!O:O,"")) | J31: =IF(COUNTBLANK(D31)=1,"",_xlfn.XLOOKUP(D31,BS_CONSOLIDADO!A:A,BS_CONSOLIDADO!P:P,"")) | L31: =IF(COUNTBLANK(D31)=1,"",_xlfn.XLOOKUP(D31,BS_SIMULADOR!A:A,BS_SIMULADOR!D:D,"")) | M31: =IF(COUNTBLANK(D31)=1,"",_xlfn.XLOOKUP(D31,BS_SIMULADOR!A:A,BS_SIMULADOR!Q:Q,"")) | N31: =IF(COUNTBLANK($D31)=1,"",_xlfn.XLOOKUP($D31,BS_SIMULADOR!$A:$A,BS_SIMULADOR!M:M,"")) | O31: =IF(COUNTBLANK(D31)=1,"",_xlfn.XLOOKUP(D31,BS_SIMULADOR!A:A,BS_SIMULADOR!N:N,"")) | P31: =IF(COUNTBLANK(D31)=1,"",_xlfn.XLOOKUP(D31,BS_SIMULADOR!A:A,BS_SIMULADOR!O:O,"")) | Q31: =IF(COUNTBLANK($D31)=1,"",_xlfn.XLOOKUP($D31,BS_SIMULADOR!$A:$A,BS_SIMULADOR!P:P,"")) | S31: =IFERROR(IF(COUNTBLANK(D31)=1,"",E31-L31)*(-1),"") | T31: =IFERROR(IF(COUNTBLANK($D31)=1,"",(_xlfn.XLOOKUP($D31,BS_CONSOLIDADO!$A:$A,BS_CONSOLIDADO!F:F,""))-(_xlfn.XLOOKUP($D31,BS_SIMULADOR!$A:$A,BS_SIMULADOR!F:F,"")))*(-1),"") | U31: =IFERROR(IF(COUNTBLANK(D31)=1,"",(_xlfn.XLOOKUP(D31,BS_CONSOLIDADO!A:A,BS_CONSOLIDADO!H:H,""))-(_xlfn.XLOOKUP(D31,BS_SIMULADOR!A:A,BS_SIMULADOR!H:H,"")))*(-1),"") | V31: =IFERROR(IF(COUNTBLANK(D31)=1,"",(_xlfn.XLOOKUP(D31,BS_CONSOLIDADO!A:A,BS_CONSOLIDADO!J:J,""))-(_xlfn.XLOOKUP(D31,BS_SIMULADOR!A:A,BS_SIMULADOR!J:J,"")))*(-1),"") | W31: =IFERROR(IF(COUNTBLANK($D31)=1,"",(_xlfn.XLOOKUP($D31,BS_CONSOLIDADO!$A:$A,BS_CONSOLIDADO!L:L,""))-(_xlfn.XLOOKUP($D31,BS_SIMULADOR!$A:$A,BS_SIMULADOR!L:L,"")))*(-1),"")
E32: =IF(COUNTBLANK(D32)=1,"",_xlfn.XLOOKUP(D32,BS_CONSOLIDADO!A:A,BS_CONSOLIDADO!D:D,"")) | F32: =IF(COUNTBLANK(D32)=1,"",_xlfn.XLOOKUP(D32,BS_CONSOLIDADO!A:A,BS_CONSOLIDADO!Q:Q,"")) | G32: =IF(COUNTBLANK($D32)=1,"",_xlfn.XLOOKUP($D32,BS_CONSOLIDADO!$A:$A,BS_CONSOLIDADO!M:M,"")) | H32: =IF(COUNTBLANK(D32)=1,"",_xlfn.XLOOKUP(D32,BS_CONSOLIDADO!A:A,BS_CONSOLIDADO!N:N,"")) | I32: =IF(COUNTBLANK(D32)=1,"",_xlfn.XLOOKUP(D32,BS_CONSOLIDADO!A:A,BS_CONSOLIDADO!O:O,"")) | J32: =IF(COUNTBLANK(D32)=1,"",_xlfn.XLOOKUP(D32,BS_CONSOLIDADO!A:A,BS_CONSOLIDADO!P:P,"")) | L32: =IF(COUNTBLANK(D32)=1,"",_xlfn.XLOOKUP(D32,BS_SIMULADOR!A:A,BS_SIMULADOR!D:D,"")) | M32: =IF(COUNTBLANK(D32)=1,"",_xlfn.XLOOKUP(D32,BS_SIMULADOR!A:A,BS_SIMULADOR!Q:Q,"")) | N32: =IF(COUNTBLANK($D32)=1,"",_xlfn.XLOOKUP($D32,BS_SIMULADOR!$A:$A,BS_SIMULADOR!M:M,"")) | O32: =IF(COUNTBLANK(D32)=1,"",_xlfn.XLOOKUP(D32,BS_SIMULADOR!A:A,BS_SIMULADOR!N:N,"")) | P32: =IF(COUNTBLANK(D32)=1,"",_xlfn.XLOOKUP(D32,BS_SIMULADOR!A:A,BS_SIMULADOR!O:O,"")) | Q32: =IF(COUNTBLANK($D32)=1,"",_xlfn.XLOOKUP($D32,BS_SIMULADOR!$A:$A,BS_SIMULADOR!P:P,"")) | S32: =IFERROR(IF(COUNTBLANK(D32)=1,"",E32-L32)*(-1),"") | T32: =IFERROR(IF(COUNTBLANK($D32)=1,"",(_xlfn.XLOOKUP($D32,BS_CONSOLIDADO!$A:$A,BS_CONSOLIDADO!F:F,""))-(_xlfn.XLOOKUP($D32,BS_SIMULADOR!$A:$A,BS_SIMULADOR!F:F,"")))*(-1),"") | U32: =IFERROR(IF(COUNTBLANK(D32)=1,"",(_xlfn.XLOOKUP(D32,BS_CONSOLIDADO!A:A,BS_CONSOLIDADO!H:H,""))-(_xlfn.XLOOKUP(D32,BS_SIMULADOR!A:A,BS_SIMULADOR!H:H,"")))*(-1),"") | V32: =IFERROR(IF(COUNTBLANK(D32)=1,"",(_xlfn.XLOOKUP(D32,BS_CONSOLIDADO!A:A,BS_CONSOLIDADO!J:J,""))-(_xlfn.XLOOKUP(D32,BS_SIMULADOR!A:A,BS_SIMULADOR!J:J,"")))*(-1),"") | W32: =IFERROR(IF(COUNTBLANK($D32)=1,"",(_xlfn.XLOOKUP($D32,BS_CONSOLIDADO!$A:$A,BS_CONSOLIDADO!L:L,""))-(_xlfn.XLOOKUP($D32,BS_SIMULADOR!$A:$A,BS_SIMULADOR!L:L,"")))*(-1),"")
E33: =IF(COUNTBLANK(D33)=1,"",_xlfn.XLOOKUP(D33,BS_CONSOLIDADO!A:A,BS_CONSOLIDADO!D:D,"")) | F33: =IF(COUNTBLANK(D33)=1,"",_xlfn.XLOOKUP(D33,BS_CONSOLIDADO!A:A,BS_CONSOLIDADO!Q:Q,"")) | G33: =IF(COUNTBLANK($D33)=1,"",_xlfn.XLOOKUP($D33,BS_CONSOLIDADO!$A:$A,BS_CONSOLIDADO!M:M,"")) | H33: =IF(COUNTBLANK(D33)=1,"",_xlfn.XLOOKUP(D33,BS_CONSOLIDADO!A:A,BS_CONSOLIDADO!N:N,"")) | I33: =IF(COUNTBLANK(D33)=1,"",_xlfn.XLOOKUP(D33,BS_CONSOLIDADO!A:A,BS_CONSOLIDADO!O:O,"")) | J33: =IF(COUNTBLANK(D33)=1,"",_xlfn.XLOOKUP(D33,BS_CONSOLIDADO!A:A,BS_CONSOLIDADO!P:P,"")) | L33: =IF(COUNTBLANK(D33)=1,"",_xlfn.XLOOKUP(D33,BS_SIMULADOR!A:A,BS_SIMULADOR!D:D,"")) | M33: =IF(COUNTBLANK(D33)=1,"",_xlfn.XLOOKUP(D33,BS_SIMULADOR!A:A,BS_SIMULADOR!Q:Q,"")) | N33: =IF(COUNTBLANK($D33)=1,"",_xlfn.XLOOKUP($D33,BS_SIMULADOR!$A:$A,BS_SIMULADOR!M:M,"")) | O33: =IF(COUNTBLANK(D33)=1,"",_xlfn.XLOOKUP(D33,BS_SIMULADOR!A:A,BS_SIMULADOR!N:N,"")) | P33: =IF(COUNTBLANK(D33)=1,"",_xlfn.XLOOKUP(D33,BS_SIMULADOR!A:A,BS_SIMULADOR!O:O,"")) | Q33: =IF(COUNTBLANK($D33)=1,"",_xlfn.XLOOKUP($D33,BS_SIMULADOR!$A:$A,BS_SIMULADOR!P:P,"")) | S33: =IFERROR(IF(COUNTBLANK(D33)=1,"",E33-L33)*(-1),"") | T33: =IFERROR(IF(COUNTBLANK($D33)=1,"",(_xlfn.XLOOKUP($D33,BS_CONSOLIDADO!$A:$A,BS_CONSOLIDADO!F:F,""))-(_xlfn.XLOOKUP($D33,BS_SIMULADOR!$A:$A,BS_SIMULADOR!F:F,"")))*(-1),"") | U33: =IFERROR(IF(COUNTBLANK(D33)=1,"",(_xlfn.XLOOKUP(D33,BS_CONSOLIDADO!A:A,BS_CONSOLIDADO!H:H,""))-(_xlfn.XLOOKUP(D33,BS_SIMULADOR!A:A,BS_SIMULADOR!H:H,"")))*(-1),"") | V33: =IFERROR(IF(COUNTBLANK(D33)=1,"",(_xlfn.XLOOKUP(D33,BS_CONSOLIDADO!A:A,BS_CONSOLIDADO!J:J,""))-(_xlfn.XLOOKUP(D33,BS_SIMULADOR!A:A,BS_SIMULADOR!J:J,"")))*(-1),"") | W33: =IFERROR(IF(COUNTBLANK($D33)=1,"",(_xlfn.XLOOKUP($D33,BS_CONSOLIDADO!$A:$A,BS_CONSOLIDADO!L:L,""))-(_xlfn.XLOOKUP($D33,BS_SIMULADOR!$A:$A,BS_SIMULADOR!L:L,"")))*(-1),"")
E34: =IF(COUNTBLANK(D34)=1,"",_xlfn.XLOOKUP(D34,BS_CONSOLIDADO!A:A,BS_CONSOLIDADO!D:D,"")) | F34: =IF(COUNTBLANK(D34)=1,"",_xlfn.XLOOKUP(D34,BS_CONSOLIDADO!A:A,BS_CONSOLIDADO!Q:Q,"")) | G34: =IF(COUNTBLANK($D34)=1,"",_xlfn.XLOOKUP($D34,BS_CONSOLIDADO!$A:$A,BS_CONSOLIDADO!M:M,"")) | H34: =IF(COUNTBLANK(D34)=1,"",_xlfn.XLOOKUP(D34,BS_CONSOLIDADO!A:A,BS_CONSOLIDADO!N:N,"")) | I34: =IF(COUNTBLANK(D34)=1,"",_xlfn.XLOOKUP(D34,BS_CONSOLIDADO!A:A,BS_CONSOLIDADO!O:O,"")) | J34: =IF(COUNTBLANK(D34)=1,"",_xlfn.XLOOKUP(D34,BS_CONSOLIDADO!A:A,BS_CONSOLIDADO!P:P,"")) | L34: =IF(COUNTBLANK(D34)=1,"",_xlfn.XLOOKUP(D34,BS_SIMULADOR!A:A,BS_SIMULADOR!D:D,"")) | M34: =IF(COUNTBLANK(D34)=1,"",_xlfn.XLOOKUP(D34,BS_SIMULADOR!A:A,BS_SIMULADOR!Q:Q,"")) | N34: =IF(COUNTBLANK($D34)=1,"",_xlfn.XLOOKUP($D34,BS_SIMULADOR!$A:$A,BS_SIMULADOR!M:M,"")) | O34: =IF(COUNTBLANK(D34)=1,"",_xlfn.XLOOKUP(D34,BS_SIMULADOR!A:A,BS_SIMULADOR!N:N,"")) | P34: =IF(COUNTBLANK(D34)=1,"",_xlfn.XLOOKUP(D34,BS_SIMULADOR!A:A,BS_SIMULADOR!O:O,"")) | Q34: =IF(COUNTBLANK($D34)=1,"",_xlfn.XLOOKUP($D34,BS_SIMULADOR!$A:$A,BS_SIMULADOR!P:P,"")) | S34: =IFERROR(IF(COUNTBLANK(D34)=1,"",E34-L34)*(-1),"") | T34: =IFERROR(IF(COUNTBLANK($D34)=1,"",(_xlfn.XLOOKUP($D34,BS_CONSOLIDADO!$A:$A,BS_CONSOLIDADO!F:F,""))-(_xlfn.XLOOKUP($D34,BS_SIMULADOR!$A:$A,BS_SIMULADOR!F:F,"")))*(-1),"") | U34: =IFERROR(IF(COUNTBLANK(D34)=1,"",(_xlfn.XLOOKUP(D34,BS_CONSOLIDADO!A:A,BS_CONSOLIDADO!H:H,""))-(_xlfn.XLOOKUP(D34,BS_SIMULADOR!A:A,BS_SIMULADOR!H:H,"")))*(-1),"") | V34: =IFERROR(IF(COUNTBLANK(D34)=1,"",(_xlfn.XLOOKUP(D34,BS_CONSOLIDADO!A:A,BS_CONSOLIDADO!J:J,""))-(_xlfn.XLOOKUP(D34,BS_SIMULADOR!A:A,BS_SIMULADOR!J:J,"")))*(-1),"") | W34: =IFERROR(IF(COUNTBLANK($D34)=1,"",(_xlfn.XLOOKUP($D34,BS_CONSOLIDADO!$A:$A,BS_CONSOLIDADO!L:L,""))-(_xlfn.XLOOKUP($D34,BS_SIMULADOR!$A:$A,BS_SIMULADOR!L:L,"")))*(-1),"")
E35: =IF(COUNTBLANK(D35)=1,"",_xlfn.XLOOKUP(D35,BS_CONSOLIDADO!A:A,BS_CONSOLIDADO!D:D,"")) | F35: =IF(COUNTBLANK(D35)=1,"",_xlfn.XLOOKUP(D35,BS_CONSOLIDADO!A:A,BS_CONSOLIDADO!Q:Q,"")) | G35: =IF(COUNTBLANK($D35)=1,"",_xlfn.XLOOKUP($D35,BS_CONSOLIDADO!$A:$A,BS_CONSOLIDADO!M:M,"")) | H35: =IF(COUNTBLANK(D35)=1,"",_xlfn.XLOOKUP(D35,BS_CONSOLIDADO!A:A,BS_CONSOLIDADO!N:N,"")) | I35: =IF(COUNTBLANK(D35)=1,"",_xlfn.XLOOKUP(D35,BS_CONSOLIDADO!A:A,BS_CONSOLIDADO!O:O,"")) | J35: =IF(COUNTBLANK(D34)=1,"",_xlfn.XLOOKUP(D34,BS_CONSOLIDADO!A:A,BS_CONSOLIDADO!P:P,"")) | L35: =IF(COUNTBLANK(D35)=1,"",_xlfn.XLOOKUP(D35,BS_SIMULADOR!A:A,BS_SIMULADOR!D:D,"")) | M35: =IF(COUNTBLANK(D35)=1,"",_xlfn.XLOOKUP(D35,BS_SIMULADOR!A:A,BS_SIMULADOR!Q:Q,"")) | N35: =IF(COUNTBLANK($D35)=1,"",_xlfn.XLOOKUP($D35,BS_SIMULADOR!$A:$A,BS_SIMULADOR!M:M,"")) | O35: =IF(COUNTBLANK(D35)=1,"",_xlfn.XLOOKUP(D35,BS_SIMULADOR!A:A,BS_SIMULADOR!N:N,"")) | P35: =IF(COUNTBLANK(D35)=1,"",_xlfn.XLOOKUP(D35,BS_SIMULADOR!A:A,BS_SIMULADOR!O:O,"")) | Q35: =IF(COUNTBLANK($D35)=1,"",_xlfn.XLOOKUP($D35,BS_SIMULADOR!$A:$A,BS_SIMULADOR!P:P,"")) | S35: =IFERROR(IF(COUNTBLANK(D35)=1,"",E35-L35)*(-1),"") | T35: =IFERROR(IF(COUNTBLANK($D35)=1,"",(_xlfn.XLOOKUP($D35,BS_CONSOLIDADO!$A:$A,BS_CONSOLIDADO!F:F,""))-(_xlfn.XLOOKUP($D35,BS_SIMULADOR!$A:$A,BS_SIMULADOR!F:F,"")))*(-1),"") | U35: =IFERROR(IF(COUNTBLANK(D35)=1,"",(_xlfn.XLOOKUP(D35,BS_CONSOLIDADO!A:A,BS_CONSOLIDADO!H:H,""))-(_xlfn.XLOOKUP(D35,BS_SIMULADOR!A:A,BS_SIMULADOR!H:H,"")))*(-1),"") | V35: =IFERROR(IF(COUNTBLANK(D35)=1,"",(_xlfn.XLOOKUP(D35,BS_CONSOLIDADO!A:A,BS_CONSOLIDADO!J:J,""))-(_xlfn.XLOOKUP(D35,BS_SIMULADOR!A:A,BS_SIMULADOR!J:J,"")))*(-1),"") | W35: =IFERROR(IF(COUNTBLANK($D35)=1,"",(_xlfn.XLOOKUP($D35,BS_CONSOLIDADO!$A:$A,BS_CONSOLIDADO!L:L,""))-(_xlfn.XLOOKUP($D35,BS_SIMULADOR!$A:$A,BS_SIMULADOR!L:L,"")))*(-1),"")
E36: =IF(COUNTBLANK(D36)=1,"",_xlfn.XLOOKUP(D36,BS_CONSOLIDADO!A:A,BS_CONSOLIDADO!D:D,"")) | F36: =IF(COUNTBLANK(D36)=1,"",_xlfn.XLOOKUP(D36,BS_CONSOLIDADO!A:A,BS_CONSOLIDADO!Q:Q,"")) | G36: =IF(COUNTBLANK($D36)=1,"",_xlfn.XLOOKUP($D36,BS_CONSOLIDADO!$A:$A,BS_CONSOLIDADO!M:M,"")) | H36: =IF(COUNTBLANK(D36)=1,"",_xlfn.XLOOKUP(D36,BS_CONSOLIDADO!A:A,BS_CONSOLIDADO!N:N,"")) | I36: =IF(COUNTBLANK(D36)=1,"",_xlfn.XLOOKUP(D36,BS_CONSOLIDADO!A:A,BS_CONSOLIDADO!O:O,"")) | J36: =IF(COUNTBLANK(D36)=1,"",_xlfn.XLOOKUP(D36,BS_CONSOLIDADO!A:A,BS_CONSOLIDADO!P:P,"")) | L36: =IF(COUNTBLANK(D36)=1,"",_xlfn.XLOOKUP(D36,BS_SIMULADOR!A:A,BS_SIMULADOR!D:D,"")) | M36: =IF(COUNTBLANK(D36)=1,"",_xlfn.XLOOKUP(D36,BS_SIMULADOR!A:A,BS_SIMULADOR!Q:Q,"")) | N36: =IF(COUNTBLANK($D36)=1,"",_xlfn.XLOOKUP($D36,BS_SIMULADOR!$A:$A,BS_SIMULADOR!M:M,"")) | O36: =IF(COUNTBLANK(D36)=1,"",_xlfn.XLOOKUP(D36,BS_SIMULADOR!A:A,BS_SIMULADOR!N:N,"")) | P36: =IF(COUNTBLANK(D36)=1,"",_xlfn.XLOOKUP(D36,BS_SIMULADOR!A:A,BS_SIMULADOR!O:O,"")) | Q36: =IF(COUNTBLANK($D36)=1,"",_xlfn.XLOOKUP($D36,BS_SIMULADOR!$A:$A,BS_SIMULADOR!P:P,"")) | S36: =IFERROR(IF(COUNTBLANK(D36)=1,"",E36-L36)*(-1),"") | T36: =IFERROR(IF(COUNTBLANK($D36)=1,"",(_xlfn.XLOOKUP($D36,BS_CONSOLIDADO!$A:$A,BS_CONSOLIDADO!F:F,""))-(_xlfn.XLOOKUP($D36,BS_SIMULADOR!$A:$A,BS_SIMULADOR!F:F,"")))*(-1),"") | U36: =IFERROR(IF(COUNTBLANK(D36)=1,"",(_xlfn.XLOOKUP(D36,BS_CONSOLIDADO!A:A,BS_CONSOLIDADO!H:H,""))-(_xlfn.XLOOKUP(D36,BS_SIMULADOR!A:A,BS_SIMULADOR!H:H,"")))*(-1),"") | V36: =IFERROR(IF(COUNTBLANK(D36)=1,"",(_xlfn.XLOOKUP(D36,BS_CONSOLIDADO!A:A,BS_CONSOLIDADO!J:J,""))-(_xlfn.XLOOKUP(D36,BS_SIMULADOR!A:A,BS_SIMULADOR!J:J,"")))*(-1),"") | W36: =IFERROR(IF(COUNTBLANK($D36)=1,"",(_xlfn.XLOOKUP($D36,BS_CONSOLIDADO!$A:$A,BS_CONSOLIDADO!L:L,""))-(_xlfn.XLOOKUP($D36,BS_SIMULADOR!$A:$A,BS_SIMULADOR!L:L,"")))*(-1),"")
E37: =IF(COUNTBLANK(D37)=1,"",_xlfn.XLOOKUP(D37,BS_CONSOLIDADO!A:A,BS_CONSOLIDADO!D:D,"")) | F37: =IF(COUNTBLANK(D37)=1,"",_xlfn.XLOOKUP(D37,BS_CONSOLIDADO!A:A,BS_CONSOLIDADO!Q:Q,"")) | G37: =IF(COUNTBLANK($D37)=1,"",_xlfn.XLOOKUP($D37,BS_CONSOLIDADO!$A:$A,BS_CONSOLIDADO!M:M,"")) | H37: =IF(COUNTBLANK(D37)=1,"",_xlfn.XLOOKUP(D37,BS_CONSOLIDADO!A:A,BS_CONSOLIDADO!N:N,"")) | I37: =IF(COUNTBLANK(D37)=1,"",_xlfn.XLOOKUP(D37,BS_CONSOLIDADO!A:A,BS_CONSOLIDADO!O:O,"")) | J37: =IF(COUNTBLANK(D37)=1,"",_xlfn.XLOOKUP(D37,BS_CONSOLIDADO!A:A,BS_CONSOLIDADO!P:P,"")) | L37: =IF(COUNTBLANK(D37)=1,"",_xlfn.XLOOKUP(D37,BS_SIMULADOR!A:A,BS_SIMULADOR!D:D,"")) | M37: =IF(COUNTBLANK(D37)=1,"",_xlfn.XLOOKUP(D37,BS_SIMULADOR!A:A,BS_SIMULADOR!Q:Q,"")) | N37: =IF(COUNTBLANK($D37)=1,"",_xlfn.XLOOKUP($D37,BS_SIMULADOR!$A:$A,BS_SIMULADOR!M:M,"")) | O37: =IF(COUNTBLANK(D37)=1,"",_xlfn.XLOOKUP(D37,BS_SIMULADOR!A:A,BS_SIMULADOR!N:N,"")) | P37: =IF(COUNTBLANK(D37)=1,"",_xlfn.XLOOKUP(D37,BS_SIMULADOR!A:A,BS_SIMULADOR!O:O,"")) | Q37: =IF(COUNTBLANK($D37)=1,"",_xlfn.XLOOKUP($D37,BS_SIMULADOR!$A:$A,BS_SIMULADOR!P:P,"")) | S37: =IFERROR(IF(COUNTBLANK(D37)=1,"",E37-L37)*(-1),"") | T37: =IFERROR(IF(COUNTBLANK($D37)=1,"",(_xlfn.XLOOKUP($D37,BS_CONSOLIDADO!$A:$A,BS_CONSOLIDADO!F:F,""))-(_xlfn.XLOOKUP($D37,BS_SIMULADOR!$A:$A,BS_SIMULADOR!F:F,"")))*(-1),"") | U37: =IFERROR(IF(COUNTBLANK(D37)=1,"",(_xlfn.XLOOKUP(D37,BS_CONSOLIDADO!A:A,BS_CONSOLIDADO!H:H,""))-(_xlfn.XLOOKUP(D37,BS_SIMULADOR!A:A,BS_SIMULADOR!H:H,"")))*(-1),"") | V37: =IFERROR(IF(COUNTBLANK(D37)=1,"",(_xlfn.XLOOKUP(D37,BS_CONSOLIDADO!A:A,BS_CONSOLIDADO!J:J,""))-(_xlfn.XLOOKUP(D37,BS_SIMULADOR!A:A,BS_SIMULADOR!J:J,"")))*(-1),"") | W37: =IFERROR(IF(COUNTBLANK($D37)=1,"",(_xlfn.XLOOKUP($D37,BS_CONSOLIDADO!$A:$A,BS_CONSOLIDADO!L:L,""))-(_xlfn.XLOOKUP($D37,BS_SIMULADOR!$A:$A,BS_SIMULADOR!L:L,"")))*(-1),"")
